Workbook

Sheet 컬렉션
A1: # | B1: 장 | C1: 타이틀 | D1: 한자 | E1: 달성 조건 | F1: 설명 | G1: 상세 설명 | H1: 칸 수 | I1: 비용 | J1: 등급 | K1: 점수 | L1: 효과 (읽는 글) | M1: 효과 종류 | N1: 대상 | O1: 능력치 | P1: 값 | Q1: 함께 참전 | R1: 함께 최소 | S1: 적진에 | T1: 도시 키
A2: 1 | B2: ① 황건 · 반동탁 (184~192) | C2: 도원결의 | D2: 桃園結義 | E2: =INDEX(칸!$I$2:$I$416,MATCH(A2,칸!$A$2:$A$416,1)) | F2: 삼국지의 시작. 세 사람은 복숭아나무 뜰에서 의형제를 맺었다고 한다. | G2: 황건적이 일어난 해, 탁현의 유비 · 관우 · 장비는 장비의 집 뒤뜰 복숭아밭에서 의형제를 맺었다. 같은 날 태어나지 못했으나 같은 날 죽기를 바란다는 맹세는 세 사람의 평생을 묶었다. | H2: =COUNTIF(칸!$A$2:$A$416,A2) | I2: =SUMIF(칸!$A$2:$A$416,A2,칸!$H$2:$H$416) | J2: =INDEX(비용표!$A$13:$A$17,MATCH(I2,비용표!$B$13:$B$17,1)) | K2: =INDEX(비용표!$C$13:$C$17,MATCH(I2,비용표!$B$13:$B$17,1)) | L2: 유비·관우·장비 함께 참전 시 유비·관우·장비 HP+2 | M2: 능력치 | N2: 유비·관우·장비 | O2: HP | P2: 2 | Q2: 유비·관우·장비
A3: 2 | B3: ① 황건 · 반동탁 (184~192) | C3: 황건적 토벌 | D3: 討黃巾賊 | E3: =INDEX(칸!$I$2:$I$416,MATCH(A3,칸!$A$2:$A$416,1)) | F3: 태평도의 장각이 일으킨 난. 훗날 천하를 나눌 세 사람이 같은 전장에 섰다. | G3: 태평도의 교주 장각이 「창천은 이미 죽었다」며 수십만 신도를 일으켰다. 토벌에 나선 관군과 의병 가운데 유비 · 조조 · 손견이 있었다 — 훗날 천하를 셋으로 나눌 이들의 첫 전장이다. | H3: =COUNTIF(칸!$A$2:$A$416,A3) | I3: =SUMIF(칸!$A$2:$A$416,A3,칸!$H$2:$H$416) | J3: =INDEX(비용표!$A$13:$A$17,MATCH(I3,비용표!$B$13:$B$17,1)) | K3: =INDEX(비용표!$C$13:$C$17,MATCH(I3,비용표!$B$13:$B$17,1)) | L3: 도적떼 약탈률 −1%p (도적 1명당 10% → 9%) | M3: 도시 | P3: 1 | T3: raidLoot
A4: 3 | B4: ① 황건 · 반동탁 (184~192) | C4: 온주참화웅 | D4: 溫酒斬華雄 | E4: =INDEX(칸!$I$2:$I$416,MATCH(A4,칸!$A$2:$A$416,1)) | F4: 데운 술이 식기 전에 화웅의 목을 베어 돌아왔다. | G4: 사수관 앞에서 동탁의 맹장 화웅이 연합군 장수들을 잇달아 베자, 마궁수에 불과하던 관우가 나섰다. 조조가 따라 준 데운 술이 식기도 전에 관우는 화웅의 목을 들고 돌아왔다고 연의는 전한다. | H4: =COUNTIF(칸!$A$2:$A$416,A4) | I4: =SUMIF(칸!$A$2:$A$416,A4,칸!$H$2:$H$416) | J4: =INDEX(비용표!$A$13:$A$17,MATCH(I4,비용표!$B$13:$B$17,1)) | K4: =INDEX(비용표!$C$13:$C$17,MATCH(I4,비용표!$B$13:$B$17,1)) | L4: 적진에 화웅 시 관우 무력+2 | M4: 능력치 | N4: 관우 | O4: 무력 | P4: 2 | S4: 화웅
A5: 4 | B5: ① 황건 · 반동탁 (184~192) | C5: 호뢰관 삼영전여포 | D5: 虎牢關三英戰呂布 | E5: =INDEX(칸!$I$2:$I$416,MATCH(A5,칸!$A$2:$A$416,1)) | F5: 세 형제가 함께 덤벼서야 여포를 물러나게 했다. | G5: 호뢰관에 나선 여포를 당할 자가 없자 장비가 맞붙었고, 관우와 유비가 차례로 뛰어들었다. 세 사람이 한꺼번에 덤벼서야 여포는 말머리를 돌렸다 — 연의가 그린 삼국 최고의 일기토다. | H5: =COUNTIF(칸!$A$2:$A$416,A5) | I5: =SUMIF(칸!$A$2:$A$416,A5,칸!$H$2:$H$416) | J5: =INDEX(비용표!$A$13:$A$17,MATCH(I5,비용표!$B$13:$B$17,1)) | K5: =INDEX(비용표!$C$13:$C$17,MATCH(I5,비용표!$B$13:$B$17,1)) | L5: 적진에 여포 시 장비 무력+2 | M5: 능력치 | N5: 장비 | O5: 무력 | P5: 2 | S5: 여포
A6: 5 | B6: ① 황건 · 반동탁 (184~192) | C6: 반동탁 연합군 | D6: 反董卓聯合軍 | E6: =INDEX(칸!$I$2:$I$416,MATCH(A6,칸!$A$2:$A$416,1)) | F6: 열여덟 제후가 낙양을 향해 모였고, 맹주는 원소였다. | G6: 동탁이 황제를 갈아 치우자 관동의 제후들이 군사를 일으켜 원소를 맹주로 세웠다. 그러나 제후들은 서로를 견제하며 나아가지 않았고, 연합은 공을 다투다 흩어졌다. | H6: =COUNTIF(칸!$A$2:$A$416,A6) | I6: =SUMIF(칸!$A$2:$A$416,A6,칸!$H$2:$H$416) | J6: =INDEX(비용표!$A$13:$A$17,MATCH(I6,비용표!$B$13:$B$17,1)) | K6: =INDEX(비용표!$C$13:$C$17,MATCH(I6,비용표!$B$13:$B$17,1)) | L6: 원소 통솔+2 | M6: 능력치 | N6: 원소 | O6: 통솔 | P6: 2
A7: 6 | B7: ① 황건 · 반동탁 (184~192) | C7: 장안 천도 | D7: 長安遷都 | E7: =INDEX(칸!$I$2:$I$416,MATCH(A7,칸!$A$2:$A$416,1)) | F7: 동탁은 낙양을 불태우고 황제와 백성을 장안으로 끌고 갔다. | G7: 연합군에 밀린 동탁은 낙양의 궁궐과 민가를 불사르고 황제와 백성 수백만을 장안으로 끌고 갔다. 길에서 쓰러진 백성이 헤아릴 수 없었고, 낙양은 폐허가 되었다. | H7: =COUNTIF(칸!$A$2:$A$416,A7) | I7: =SUMIF(칸!$A$2:$A$416,A7,칸!$H$2:$H$416) | J7: =INDEX(비용표!$A$13:$A$17,MATCH(I7,비용표!$B$13:$B$17,1)) | K7: =INDEX(비용표!$C$13:$C$17,MATCH(I7,비용표!$B$13:$B$17,1)) | L7: 동탁 HP+1 | M7: 능력치 | N7: 동탁 | O7: HP | P7: 1
A8: 7 | B8: ① 황건 · 반동탁 (184~192) | C8: 칠성보도 헌상 | D8: 獻七星寶刀 | E8: =INDEX(칸!$I$2:$I$416,MATCH(A8,칸!$A$2:$A$416,1)) | F8: 동탁을 찌르려던 칼은 들키는 순간 헌상품이 되었다. | G8: 왕윤에게서 칠성보도를 빌린 조조는 동탁의 침소에서 칼을 뽑았으나, 거울에 비친 모습에 동탁이 돌아보았다. 조조는 칼을 바치러 왔다며 무릎을 꿇었고, 그 길로 낙양을 빠져나갔다. | H8: =COUNTIF(칸!$A$2:$A$416,A8) | I8: =SUMIF(칸!$A$2:$A$416,A8,칸!$H$2:$H$416) | J8: =INDEX(비용표!$A$13:$A$17,MATCH(I8,비용표!$B$13:$B$17,1)) | K8: =INDEX(비용표!$C$13:$C$17,MATCH(I8,비용표!$B$13:$B$17,1)) | L8: 적진에 동탁 시 조조 무력+2 | M8: 능력치 | N8: 조조 | O8: 무력 | P8: 2 | S8: 동탁
A9: 8 | B9: ① 황건 · 반동탁 (184~192) | C9: 진궁의 결별 | D9: 陳宮決別 | E9: =INDEX(칸!$I$2:$I$416,MATCH(A9,칸!$A$2:$A$416,1)) | F9: 「차라리 내가 천하를 버릴지언정」 — 진궁은 그 밤에 조조를 떠났다. | G9: 동탁을 피해 달아나던 조조를 현령 진궁이 풀어 주고 함께 길을 떠났다. 그러나 여백사 일가를 오해로 죽이고도 「내가 천하를 버릴지언정」이라 말하는 조조를 보고, 진궁은 그 밤에 떠났다. | H9: =COUNTIF(칸!$A$2:$A$416,A9) | I9: =SUMIF(칸!$A$2:$A$416,A9,칸!$H$2:$H$416) | J9: =INDEX(비용표!$A$13:$A$17,MATCH(I9,비용표!$B$13:$B$17,1)) | K9: =INDEX(비용표!$C$13:$C$17,MATCH(I9,비용표!$B$13:$B$17,1)) | L9: 적진에 조조 시 진궁 통솔+1 | M9: 능력치 | N9: 진궁 | O9: 통솔 | P9: 1 | S9: 조조
A10: 9 | B10: ① 황건 · 반동탁 (184~192) | C10: 형양의 추격 | D10: 滎陽追擊 | E10: =INDEX(칸!$I$2:$I$416,MATCH(A10,칸!$A$2:$A$416,1)) | F10: 「천하에 조홍은 없어도 되지만 공은 없어선 안 됩니다.」 — 조홍은 제 말을 내주었다. | G10: 연합군 중 홀로 동탁을 추격한 조조는 형양에서 서영에게 크게 졌다. 말을 잃고 쓰러진 조조에게 조홍이 제 말을 내주며 「천하에 조홍은 없어도 되지만 공은 없어선 안 됩니다」라 했다. | H10: =COUNTIF(칸!$A$2:$A$416,A10) | I10: =SUMIF(칸!$A$2:$A$416,A10,칸!$H$2:$H$416) | J10: =INDEX(비용표!$A$13:$A$17,MATCH(I10,비용표!$B$13:$B$17,1)) | K10: =INDEX(비용표!$C$13:$C$17,MATCH(I10,비용표!$B$13:$B$17,1)) | L10: 조조 함께 참전 시 조홍 HP+2 | M10: 능력치 | N10: 조홍 | O10: HP | P10: 2 | Q10: 조조
A11: 10 | B11: ① 황건 · 반동탁 (184~192) | C11: 손견과 전국옥새 | D11: 孫堅得玉璽 | E11: =INDEX(칸!$I$2:$I$416,MATCH(A11,칸!$A$2:$A$416,1)) | F11: 불탄 낙양의 우물에서 건져 올린 황제의 옥새. | G11: 불탄 낙양에 먼저 들어간 손견은 궁궐 우물에서 황제의 옥새를 건졌다. 옥새를 숨긴 채 강동으로 돌아가려던 손견은 원소 · 유표와 원수가 되었다. | H11: =COUNTIF(칸!$A$2:$A$416,A11) | I11: =SUMIF(칸!$A$2:$A$416,A11,칸!$H$2:$H$416) | J11: =INDEX(비용표!$A$13:$A$17,MATCH(I11,비용표!$B$13:$B$17,1)) | K11: =INDEX(비용표!$C$13:$C$17,MATCH(I11,비용표!$B$13:$B$17,1)) | L11: 손견 통솔+2 | M11: 능력치 | N11: 손견 | O11: 통솔 | P11: 2
A12: 11 | B12: ① 황건 · 반동탁 (184~192) | C12: 현산의 손견 | D12: 峴山伏兵 | E12: =INDEX(칸!$I$2:$I$416,MATCH(A12,칸!$A$2:$A$416,1)) | F12: 강동의 호랑이는 괴월의 매복에 걸려 현산에서 쓰러졌다. | G12: 원술의 명으로 형주를 친 손견은 유표의 장수 황조를 몰아붙였다. 그러나 괴월의 계책으로 현산에 숨은 복병에게 돌과 화살을 맞아, 강동의 호랑이는 서른일곱에 쓰러졌다. | H12: =COUNTIF(칸!$A$2:$A$416,A12) | I12: =SUMIF(칸!$A$2:$A$416,A12,칸!$H$2:$H$416) | J12: =INDEX(비용표!$A$13:$A$17,MATCH(I12,비용표!$B$13:$B$17,1)) | K12: =INDEX(비용표!$C$13:$C$17,MATCH(I12,비용표!$B$13:$B$17,1)) | L12: 적진에 손견 시 괴월 지력+2 | M12: 능력치 | N12: 괴월 | O12: 지력 | P12: 2 | S12: 손견
A13: 12 | B13: ① 황건 · 반동탁 (184~192) | C13: 백마의종 | D13: 白馬義從 | E13: =INDEX(칸!$I$2:$I$416,MATCH(A13,칸!$A$2:$A$416,1)) | F13: 흰 말만 골라 탄 공손찬의 기병대는 이민족도 두려워했다. | G13: 공손찬은 흰 말을 탄 활 잘 쏘는 기병 수천을 골라 「백마의종」이라 불렀다. 북방의 오환은 흰 말만 보면 달아났다고 하니, 그 이름만으로도 변경을 지켰다. | H13: =COUNTIF(칸!$A$2:$A$416,A13) | I13: =SUMIF(칸!$A$2:$A$416,A13,칸!$H$2:$H$416) | J13: =INDEX(비용표!$A$13:$A$17,MATCH(I13,비용표!$B$13:$B$17,1)) | K13: =INDEX(비용표!$C$13:$C$17,MATCH(I13,비용표!$B$13:$B$17,1)) | L13: 공손찬 통솔+2 | M13: 능력치 | N13: 공손찬 | O13: 통솔 | P13: 2
A14: 13 | B14: ① 황건 · 반동탁 (184~192) | C14: 계교 전투 | D14: 界橋之戰 | E14: =INDEX(칸!$I$2:$I$416,MATCH(A14,칸!$A$2:$A$416,1)) | F14: 국의의 강노병이 백마의종을 무너뜨렸다. | G14: 원소와 공손찬이 기주를 두고 계교에서 맞섰다. 원소의 장수 국의는 강노병 팔백을 방패 뒤에 숨겼다가 백마의종이 코앞에 오자 일제히 쏘아 무너뜨렸다. | H14: =COUNTIF(칸!$A$2:$A$416,A14) | I14: =SUMIF(칸!$A$2:$A$416,A14,칸!$H$2:$H$416) | J14: =INDEX(비용표!$A$13:$A$17,MATCH(I14,비용표!$B$13:$B$17,1)) | K14: =INDEX(비용표!$C$13:$C$17,MATCH(I14,비용표!$B$13:$B$17,1)) | L14: 적진에 공손찬 시 국의 무력+2 | M14: 능력치 | N14: 국의 | O14: 무력 | P14: 2 | S14: 공손찬
A15: 14 | B15: ② 군웅할거 (192~199) | C15: 이각과 곽사 | D15: 李傕郭汜 | E15: =INDEX(칸!$I$2:$I$416,MATCH(A15,칸!$A$2:$A$416,1)) | F15: 동탁이 죽은 뒤 장안을 차지한 두 장수는 곧 서로를 공격했다. | G15: 왕윤과 여포가 동탁을 죽이자, 그 부장 이각과 곽사는 장안을 들이쳐 조정을 손에 넣었다. 그러나 둘은 곧 서로를 의심해 장안 한복판에서 싸웠고, 황제와 대신들은 인질이 되었다. | H15: =COUNTIF(칸!$A$2:$A$416,A15) | I15: =SUMIF(칸!$A$2:$A$416,A15,칸!$H$2:$H$416) | J15: =INDEX(비용표!$A$13:$A$17,MATCH(I15,비용표!$B$13:$B$17,1)) | K15: =INDEX(비용표!$C$13:$C$17,MATCH(I15,비용표!$B$13:$B$17,1)) | L15: 이각·곽사 함께 참전 시 이각·곽사 HP+1 | M15: 능력치 | N15: 이각·곽사 | O15: HP | P15: 1 | Q15: 이각·곽사
A16: 15 | B16: ② 군웅할거 (192~199) | C16: 헌제의 동귀 | D16: 獻帝東歸 | E16: =INDEX(칸!$I$2:$I$416,MATCH(A16,칸!$A$2:$A$416,1)) | F16: 이각 · 곽사에게 쫓기던 황제를, 순욱의 「봉천자」 계책대로 조조가 허도로 맞았다. | G16: 이각과 곽사에게 쫓기던 헌제는 한섬 · 서황의 호위를 받아 폐허가 된 낙양으로 돌아왔다. 순욱은 「천자를 받들어 천하를 호령하라」 권했고, 조조는 황제를 허도로 맞았다. | H16: =COUNTIF(칸!$A$2:$A$416,A16) | I16: =SUMIF(칸!$A$2:$A$416,A16,칸!$H$2:$H$416) | J16: =INDEX(비용표!$A$13:$A$17,MATCH(I16,비용표!$B$13:$B$17,1)) | K16: =INDEX(비용표!$C$13:$C$17,MATCH(I16,비용표!$B$13:$B$17,1)) | L16: 헌제의 「황제옹립」 SP 7 → 6 | M16: 고유기술SP | N16: 헌제 | P16: -1
A17: 16 | B17: ② 군웅할거 (192~199) | C17: 둔전제 | D17: 屯田制 | E17: =INDEX(칸!$I$2:$I$416,MATCH(A17,칸!$A$2:$A$416,1)) | F17: 유민에게 땅과 소를 주어 군량을 쌓았다. 조조 패업의 밑돌이다. | G17: 전란으로 굶주린 유민이 넘치자 조조는 한호 · 조지의 건의로 둔전을 열었다. 백성과 병사에게 땅과 소를 나눠 농사를 짓게 하니 한 해에 백만 섬이 쌓였다. | H17: =COUNTIF(칸!$A$2:$A$416,A17) | I17: =SUMIF(칸!$A$2:$A$416,A17,칸!$H$2:$H$416) | J17: =INDEX(비용표!$A$13:$A$17,MATCH(I17,비용표!$B$13:$B$17,1)) | K17: =INDEX(비용표!$C$13:$C$17,MATCH(I17,비용표!$B$13:$B$17,1)) | L17: 군량 충전 속도 +5% | M17: 도시 | P17: 5 | T17: grainRate
A18: 17 | B18: ② 군웅할거 (192~199) | C18: 서주 양도 | D18: 三讓徐州 | E18: =INDEX(칸!$I$2:$I$416,MATCH(A18,칸!$A$2:$A$416,1)) | F18: 도겸은 세 번 서주를 내밀었고 유비는 세 번 사양했다. | G18: 조조의 공격에 시달리던 서주목 도겸은 죽음을 앞두고 유비에게 서주를 맡기려 했다. 유비는 세 번 사양하다 미축 · 손건의 간청에 받아들였다. | H18: =COUNTIF(칸!$A$2:$A$416,A18) | I18: =SUMIF(칸!$A$2:$A$416,A18,칸!$H$2:$H$416) | J18: =INDEX(비용표!$A$13:$A$17,MATCH(I18,비용표!$B$13:$B$17,1)) | K18: =INDEX(비용표!$C$13:$C$17,MATCH(I18,비용표!$B$13:$B$17,1)) | L18: 유비 통솔+1 | M18: 능력치 | N18: 유비 | O18: 통솔 | P18: 1
A19: 18 | B19: ② 군웅할거 (192~199) | C19: 술 취한 장비 | D19: 張飛醉失徐州 | E19: =INDEX(칸!$I$2:$I$416,MATCH(A19,칸!$A$2:$A$416,1)) | F19: 장비가 취해 매질한 조표는 그날 밤 여포에게 성문을 열었다. | G19: 서주를 지키던 장비는 술자리에서 조표를 매질했다. 앙심을 품은 조표가 사위 여포에게 밤중에 성문을 열어 주어, 장비는 서주를 잃고 형님을 볼 낯이 없었다. | H19: =COUNTIF(칸!$A$2:$A$416,A19) | I19: =SUMIF(칸!$A$2:$A$416,A19,칸!$H$2:$H$416) | J19: =INDEX(비용표!$A$13:$A$17,MATCH(I19,비용표!$B$13:$B$17,1)) | K19: =INDEX(비용표!$C$13:$C$17,MATCH(I19,비용표!$B$13:$B$17,1)) | L19: 적진에 장비 시 조표 무력+2 | M19: 능력치 | N19: 조표 | O19: 무력 | P19: 2 | S19: 장비
A20: 19 | B20: ② 군웅할거 (192~199) | C20: 원문사극 | D20: 轅門射戟 | E20: =INDEX(칸!$I$2:$I$416,MATCH(A20,칸!$A$2:$A$416,1)) | F20: 군문 밖 백오십 보의 화극을 맞히면 싸우지 말라. | G20: 원술의 장수 기령이 유비를 치러 오자 여포가 두 사람을 불렀다. 군문 밖 백오십 보에 화극을 세우고 「한 발에 맞히면 싸우지 말라」 하더니, 화살은 정확히 화극의 곁가지에 꽂혔다. | H20: =COUNTIF(칸!$A$2:$A$416,A20) | I20: =SUMIF(칸!$A$2:$A$416,A20,칸!$H$2:$H$416) | J20: =INDEX(비용표!$A$13:$A$17,MATCH(I20,비용표!$B$13:$B$17,1)) | K20: =INDEX(비용표!$C$13:$C$17,MATCH(I20,비용표!$B$13:$B$17,1)) | L20: 여포 HP+1 | M20: 능력치 | N20: 여포 | O20: HP | P20: 1
A21: 20 | B21: ② 군웅할거 (192~199) | C21: 공융과 태사자 | D21: 太史慈救北海 | E21: =INDEX(칸!$I$2:$I$416,MATCH(A21,칸!$A$2:$A$416,1)) | F21: 포위된 북해를 구하러 태사자가 홀로 적진을 뚫었다. | G21: 황건 잔당에 포위된 북해의 공융을 위해, 은혜를 입은 태사자가 홀로 포위를 뚫고 유비에게 구원을 청했다. 유비가 「공북해가 이 유비를 아는가」 하며 기뻐 군사를 냈다. | H21: =COUNTIF(칸!$A$2:$A$416,A21) | I21: =SUMIF(칸!$A$2:$A$416,A21,칸!$H$2:$H$416) | J21: =INDEX(비용표!$A$13:$A$17,MATCH(I21,비용표!$B$13:$B$17,1)) | K21: =INDEX(비용표!$C$13:$C$17,MATCH(I21,비용표!$B$13:$B$17,1)) | L21: 태사자 함께 참전 시 공융 통솔+2 | M21: 능력치 | N21: 공융 | O21: 통솔 | P21: 2 | Q21: 태사자
A22: 21 | B22: ② 군웅할거 (192~199) | C22: 인중여포 마중적토 | D22: 人中呂布馬中赤兔 | E22: =INDEX(칸!$I$2:$I$416,MATCH(A22,칸!$A$2:$A$416,1)) | F22: 삼국지 역사상 최강의 사나이. 사람 중에는 여포, 말 중에는 적토. | G22: 「사람 중에는 여포, 말 중에는 적토마.」 방천화극을 들고 적토마를 탄 여포는 당대 누구도 정면으로 이기지 못한 무인이었다. 다만 그 곁의 진궁 · 고순 · 장료의 말을 끝내 듣지 않았다. | H22: =COUNTIF(칸!$A$2:$A$416,A22) | I22: =SUMIF(칸!$A$2:$A$416,A22,칸!$H$2:$H$416) | J22: =INDEX(비용표!$A$13:$A$17,MATCH(I22,비용표!$B$13:$B$17,1)) | K22: =INDEX(비용표!$C$13:$C$17,MATCH(I22,비용표!$B$13:$B$17,1)) | L22: 여포의 「인중여포 마중적토」 SP 6 → 5 | M22: 고유기술SP | N22: 여포 | P22: -1
A23: 22 | B23: ② 군웅할거 (192~199) | C23: 함진영 | D23: 陷陣營 | E23: =INDEX(칸!$I$2:$I$416,MATCH(A23,칸!$A$2:$A$416,1)) | F23: 칠백 명으로 공격하면 반드시 깨뜨렸다는 고순의 정예. | G23: 여포의 장수 고순은 칠백 명을 거느렸는데, 갑옷과 무기가 정예하여 「함진영」이라 불렀다. 공격하면 반드시 적진을 깨뜨렸으나, 여포는 그를 믿으면서도 끝내 중히 쓰지 않았다. | H23: =COUNTIF(칸!$A$2:$A$416,A23) | I23: =SUMIF(칸!$A$2:$A$416,A23,칸!$H$2:$H$416) | J23: =INDEX(비용표!$A$13:$A$17,MATCH(I23,비용표!$B$13:$B$17,1)) | K23: =INDEX(비용표!$C$13:$C$17,MATCH(I23,비용표!$B$13:$B$17,1)) | L23: 고순 통솔+1 | M23: 능력치 | N23: 고순 | O23: 통솔 | P23: 1
A24: 23 | B24: ② 군웅할거 (192~199) | C24: 하비성 백문루 | D24: 白門樓 | E24: =INDEX(칸!$I$2:$I$416,MATCH(A24,칸!$A$2:$A$416,1)) | F24: 부하들이 등을 돌렸고, 여포는 백문루에서 묶였다. | G24: 조조가 사수와 기수를 터 하비성을 물에 잠기게 하자 여포의 부하들이 등을 돌렸다. 후성 · 송헌 · 위속이 진궁을 묶어 바쳤고, 여포는 백문루에서 사로잡혀 목숨을 잃었다. | H24: =COUNTIF(칸!$A$2:$A$416,A24) | I24: =SUMIF(칸!$A$2:$A$416,A24,칸!$H$2:$H$416) | J24: =INDEX(비용표!$A$13:$A$17,MATCH(I24,비용표!$B$13:$B$17,1)) | K24: =INDEX(비용표!$C$13:$C$17,MATCH(I24,비용표!$B$13:$B$17,1)) | L24: 여포 함께 참전 시 진궁 지력+2 | M24: 능력치 | N24: 진궁 | O24: 지력 | P24: 2 | Q24: 여포
A25: 24 | B25: ② 군웅할거 (192~199) | C25: 진등 부자 | D25: 陳登父子 | E25: =INDEX(칸!$I$2:$I$416,MATCH(A25,칸!$A$2:$A$416,1)) | F25: 진등은 겉으로 여포를 섬기며 안으로 조조와 손을 잡았다. | G25: 서주의 진규 · 진등 부자는 겉으로 여포를 섬기며 안으로 조조와 통했다. 진등이 조조에게서 받은 광릉태수의 인수가, 여포를 무너뜨린 마지막 고리가 되었다. | H25: =COUNTIF(칸!$A$2:$A$416,A25) | I25: =SUMIF(칸!$A$2:$A$416,A25,칸!$H$2:$H$416) | J25: =INDEX(비용표!$A$13:$A$17,MATCH(I25,비용표!$B$13:$B$17,1)) | K25: =INDEX(비용표!$C$13:$C$17,MATCH(I25,비용표!$B$13:$B$17,1)) | L25: 진등 지력+2 | M25: 능력치 | N25: 진등 | O25: 지력 | P25: 2
A26: 25 | B26: ② 군웅할거 (192~199) | C26: 원술 칭제 | D26: 袁術稱帝 | E26: =INDEX(칸!$I$2:$I$416,MATCH(A26,칸!$A$2:$A$416,1)) | F26: 옥새를 품고 황제를 칭했으나 마지막엔 꿀물 한 그릇을 찾았다. | G26: 손견이 남긴 옥새를 손에 넣은 원술은 수춘에서 스스로 황제를 칭했다. 그러나 사치와 실정에 백성과 장수가 등을 돌렸고, 마지막에는 꿀물 한 그릇을 찾다 피를 토하고 죽었다. | H26: =COUNTIF(칸!$A$2:$A$416,A26) | I26: =SUMIF(칸!$A$2:$A$416,A26,칸!$H$2:$H$416) | J26: =INDEX(비용표!$A$13:$A$17,MATCH(I26,비용표!$B$13:$B$17,1)) | K26: =INDEX(비용표!$C$13:$C$17,MATCH(I26,비용표!$B$13:$B$17,1)) | L26: 최대 군량 +2 | M26: 도시 | P26: 2 | T26: grainCap
A27: 26 | B27: ② 군웅할거 (192~199) | C27: 역경 함락 | D27: 易京陷落 | E27: =INDEX(칸!$I$2:$I$416,MATCH(A27,칸!$A$2:$A$416,1)) | F27: 높은 누대에 숨은 공손찬은 땅굴을 판 원소군 앞에 스스로 불을 질렀다. | G27: 원소에게 밀린 공손찬은 역경에 수십 장 높이의 누대를 쌓고 틀어박혔다. 원소군이 땅굴을 파고 들어와 누대를 무너뜨리자, 공손찬은 처자를 죽이고 스스로 불을 질렀다. | H27: =COUNTIF(칸!$A$2:$A$416,A27) | I27: =SUMIF(칸!$A$2:$A$416,A27,칸!$H$2:$H$416) | J27: =INDEX(비용표!$A$13:$A$17,MATCH(I27,비용표!$B$13:$B$17,1)) | K27: =INDEX(비용표!$C$13:$C$17,MATCH(I27,비용표!$B$13:$B$17,1)) | L27: 공손찬 HP+1 | M27: 능력치 | N27: 공손찬 | O27: HP | P27: 1
A28: 27 | B28: ② 군웅할거 (192~199) | C28: 신정산의 일기토 | D28: 神亭山一騎討 | E28: =INDEX(칸!$I$2:$I$416,MATCH(A28,칸!$A$2:$A$416,1)) | F28: 태사자는 두 자루 극을 들고 소패왕과 맞붙었다. | G28: 신정산에서 정찰하던 손책과 맞닥뜨린 태사자는 홀로 덤벼들었다. 둘은 말에서 떨어져 뒤엉켰고, 손책은 태사자의 단극을, 태사자는 손책의 투구를 빼앗았다. 이후 태사자는 손책의 장수가 되었다. | H28: =COUNTIF(칸!$A$2:$A$416,A28) | I28: =SUMIF(칸!$A$2:$A$416,A28,칸!$H$2:$H$416) | J28: =INDEX(비용표!$A$13:$A$17,MATCH(I28,비용표!$B$13:$B$17,1)) | K28: =INDEX(비용표!$C$13:$C$17,MATCH(I28,비용표!$B$13:$B$17,1)) | L28: 태사자 무력+1 | M28: 능력치 | N28: 태사자 | O28: 무력 | P28: 1
A29: 28 | B29: ② 군웅할거 (192~199) | C29: 내사는 장소에게 | D29: 內事問張昭 | E29: =INDEX(칸!$I$2:$I$416,MATCH(A29,칸!$A$2:$A$416,1)) | F29: 「안의 일은 장소에게, 밖의 일은 주유에게 물어라.」 — 손책의 유언. | G29: 자객의 화살에 쓰러진 손책은 열여덟 살 아우 손권에게 인수를 넘겼다. 「안의 일은 장소에게, 밖의 일은 주유에게 물어라」 — 손권은 그 두 사람과 함께 강동을 지켜 냈다. | H29: =COUNTIF(칸!$A$2:$A$416,A29) | I29: =SUMIF(칸!$A$2:$A$416,A29,칸!$H$2:$H$416) | J29: =INDEX(비용표!$A$13:$A$17,MATCH(I29,비용표!$B$13:$B$17,1)) | K29: =INDEX(비용표!$C$13:$C$17,MATCH(I29,비용표!$B$13:$B$17,1)) | L29: 장소 통솔+2 | M29: 능력치 | N29: 장소 | O29: 통솔 | P29: 2
A30: 29 | B30: ② 군웅할거 (192~199) | C30: 완성의 밤 | D30: 宛城之夜 | E30: =INDEX(칸!$I$2:$I$416,MATCH(A30,칸!$A$2:$A$416,1)) | F30: 조조는 이 밤 장자와 조카, 그리고 명마 절영을 잃었다. | G30: 장수의 항복을 받아들인 조조는 완성에서 그 숙모를 취했다. 분노한 장수가 가후의 계책으로 밤에 들이치니, 조조는 장자 조앙과 조카, 맹장 전위, 명마 절영을 잃고 겨우 살아났다. | H30: =COUNTIF(칸!$A$2:$A$416,A30) | I30: =SUMIF(칸!$A$2:$A$416,A30,칸!$H$2:$H$416) | J30: =INDEX(비용표!$A$13:$A$17,MATCH(I30,비용표!$B$13:$B$17,1)) | K30: =INDEX(비용표!$C$13:$C$17,MATCH(I30,비용표!$B$13:$B$17,1)) | L30: 장수 통솔+2 | M30: 능력치 | N30: 장수 | O30: 통솔 | P30: 2
A31: 30 | B31: ② 군웅할거 (192~199) | C31: 가후의 계책 | D31: 賈詡之計 | E31: =INDEX(칸!$I$2:$I$416,MATCH(A31,칸!$A$2:$A$416,1)) | F31: 추격하지 말라 할 때 추격하고, 추격하라 할 때 물러서게 했다. | G31: 물러나는 조조를 장수가 추격하려 하자 가후가 말렸다. 장수가 듣지 않고 쫓다 지고 오자, 가후는 「이제 다시 쫓으라」 했고 이번에는 크게 이겼다 — 적의 마음을 읽은 계책이었다. | H31: =COUNTIF(칸!$A$2:$A$416,A31) | I31: =SUMIF(칸!$A$2:$A$416,A31,칸!$H$2:$H$416) | J31: =INDEX(비용표!$A$13:$A$17,MATCH(I31,비용표!$B$13:$B$17,1)) | K31: =INDEX(비용표!$C$13:$C$17,MATCH(I31,비용표!$B$13:$B$17,1)) | L31: 가후 통솔+1 | M31: 능력치 | N31: 가후 | O31: 통솔 | P31: 1
A32: 31 | B32: ② 군웅할거 (192~199) | C32: 청매자주 영웅론 | D32: 青梅煮酒論英雄 | E32: =INDEX(칸!$I$2:$I$416,MATCH(A32,칸!$A$2:$A$416,1)) | F32: 「천하의 영웅은 그대와 나뿐이오」 — 유비는 젓가락을 떨어뜨렸다. | G32: 조조는 유비를 불러 매실을 안주 삼아 술을 데우며 천하의 영웅을 논했다. 「천하의 영웅은 그대와 나뿐」이라는 말에 유비가 젓가락을 떨어뜨리자, 마침 친 천둥소리에 놀란 척 둘러댔다. | H32: =COUNTIF(칸!$A$2:$A$416,A32) | I32: =SUMIF(칸!$A$2:$A$416,A32,칸!$H$2:$H$416) | J32: =INDEX(비용표!$A$13:$A$17,MATCH(I32,비용표!$B$13:$B$17,1)) | K32: =INDEX(비용표!$C$13:$C$17,MATCH(I32,비용표!$B$13:$B$17,1)) | L32: 적진에 유비 시 조조 지력+2 | M32: 능력치 | N32: 조조 | O32: 지력 | P32: 2 | S32: 유비
A33: 32 | B33: ② 군웅할거 (192~199) | C33: 의대조 | D33: 衣帶詔 | E33: =INDEX(칸!$I$2:$I$416,MATCH(A33,칸!$A$2:$A$416,1)) | F33: 황제의 옷 띠 속에 조조를 치라는 피의 밀서가 꿰매져 있었다. | G33: 조조의 전횡에 헌제는 피로 쓴 밀조를 옷 띠 속에 꿰매 동승에게 내렸다. 유비 · 마등이 이름을 올렸으나 계획은 탄로 나, 동승의 일족은 몰살되고 유비는 서주로 달아났다. | H33: =COUNTIF(칸!$A$2:$A$416,A33) | I33: =SUMIF(칸!$A$2:$A$416,A33,칸!$H$2:$H$416) | J33: =INDEX(비용표!$A$13:$A$17,MATCH(I33,비용표!$B$13:$B$17,1)) | K33: =INDEX(비용표!$C$13:$C$17,MATCH(I33,비용표!$B$13:$B$17,1)) | L33: 유비 함께 참전 시 헌제 HP+1 | M33: 능력치 | N33: 헌제 | O33: HP | P33: 1 | Q33: 유비
A34: 33 | B34: ③ 관도 (200~207) | C34: 토산의 세 가지 약속 | D34: 土山約三事 | E34: =INDEX(칸!$I$2:$I$416,MATCH(A34,칸!$A$2:$A$416,1)) | F34: 장료의 설득에 관우는 세 가지를 약속받고서야 항복했다. | G34: 하비에서 포위된 관우를 장료가 찾아와 설득했다. 관우는 한에 항복하되 조조에게 항복하지 않는다, 두 형수를 모신다, 유비의 소식을 들으면 떠난다 — 세 가지를 약속받고서야 칼을 내려놓았다. | H34: =COUNTIF(칸!$A$2:$A$416,A34) | I34: =SUMIF(칸!$A$2:$A$416,A34,칸!$H$2:$H$416) | J34: =INDEX(비용표!$A$13:$A$17,MATCH(I34,비용표!$B$13:$B$17,1)) | K34: =INDEX(비용표!$C$13:$C$17,MATCH(I34,비용표!$B$13:$B$17,1)) | L34: 장료 지력+1 | M34: 능력치 | N34: 장료 | O34: 지력 | P34: 1
A35: 34 | B35: ③ 관도 (200~207) | C35: 십승십패론 | D35: 十勝十敗論 | E35: =INDEX(칸!$I$2:$I$416,MATCH(A35,칸!$A$2:$A$416,1)) | F35: 곽가는 조조가 원소를 이길 열 가지 이유를 들었다. | G35: 원소의 오만한 편지에 조조가 근심하자, 곽가는 조조가 원소를 이길 열 가지와 원소가 질 열 가지를 들었다(『부자』). 도량 · 결단 · 용병 · 덕 — 그 말은 관도대전의 예언이 되었다. | H35: =COUNTIF(칸!$A$2:$A$416,A35) | I35: =SUMIF(칸!$A$2:$A$416,A35,칸!$H$2:$H$416) | J35: =INDEX(비용표!$A$13:$A$17,MATCH(I35,비용표!$B$13:$B$17,1)) | K35: =INDEX(비용표!$C$13:$C$17,MATCH(I35,비용표!$B$13:$B$17,1)) | L35: 곽가 통솔+2 | M35: 능력치 | N35: 곽가 | O35: 통솔 | P35: 2
A36: 35 | B36: ③ 관도 (200~207) | C36: 왕좌지재 | D36: 王佐之才 | E36: =INDEX(칸!$I$2:$I$416,MATCH(A36,칸!$A$2:$A$416,1)) | F36: 조조는 순욱을 「나의 자방」이라 불렀다. | G36: 조조는 원소를 떠나 찾아온 순욱을 보고 「나의 자방이 왔다」며 기뻐했다. 순욱은 조카 순유와 함께 조조의 모든 큰 결정에 함께했고, 허도를 지키며 천하를 경영했다. | H36: =COUNTIF(칸!$A$2:$A$416,A36) | I36: =SUMIF(칸!$A$2:$A$416,A36,칸!$H$2:$H$416) | J36: =INDEX(비용표!$A$13:$A$17,MATCH(I36,비용표!$B$13:$B$17,1)) | K36: =INDEX(비용표!$C$13:$C$17,MATCH(I36,비용표!$B$13:$B$17,1)) | L36: 순욱 함께 참전 시 순유 통솔+2 | M36: 능력치 | N36: 순유 | O36: 통솔 | P36: 2 | Q36: 순욱
A37: 36 | B37: ③ 관도 (200~207) | C37: 원소의 모사들 | D37: 袁紹謀士 | E37: =INDEX(칸!$I$2:$I$416,MATCH(A37,칸!$A$2:$A$416,1)) | F37: 책사는 넘쳤으나 주군은 끝내 어느 말도 듣지 않았다. | G37: 원소의 막하에는 전풍 · 저수 · 심배 · 봉기 · 곽도 · 허유가 있었으나 서로를 헐뜯었다. 원소는 옳은 말을 하는 자를 가두고 듣기 좋은 말만 들었으니, 책사는 많아도 계책은 없었다. | H37: =COUNTIF(칸!$A$2:$A$416,A37) | I37: =SUMIF(칸!$A$2:$A$416,A37,칸!$H$2:$H$416) | J37: =INDEX(비용표!$A$13:$A$17,MATCH(I37,비용표!$B$13:$B$17,1)) | K37: =INDEX(비용표!$C$13:$C$17,MATCH(I37,비용표!$B$13:$B$17,1)) | L37: 전풍·저수 함께 참전 시 전풍·저수 MP+1 | M37: 능력치 | N37: 전풍·저수 | O37: MP | P37: 1 | Q37: 전풍·저수
A38: 37 | B38: ③ 관도 (200~207) | C38: 하북의 두 기둥 | D38: 河北雙壁 | E38: =INDEX(칸!$I$2:$I$416,MATCH(A38,칸!$A$2:$A$416,1)) | F38: 원소군 최강의 두 장수. 둘이 함께면 당할 자가 없다 했다. | G38: 안량과 문추는 원소군을 대표하는 맹장으로 하북의 두 기둥이라 불렸다. 그러나 안량은 백마에서 관우에게, 문추는 연진에서 조조군에게 차례로 쓰러져 원소의 사기를 꺾었다. | H38: =COUNTIF(칸!$A$2:$A$416,A38) | I38: =SUMIF(칸!$A$2:$A$416,A38,칸!$H$2:$H$416) | J38: =INDEX(비용표!$A$13:$A$17,MATCH(I38,비용표!$B$13:$B$17,1)) | K38: =INDEX(비용표!$C$13:$C$17,MATCH(I38,비용표!$B$13:$B$17,1)) | L38: 안량·문추 함께 참전 시 안량·문추 무력+1 | M38: 능력치 | N38: 안량·문추 | O38: 무력 | P38: 1 | Q38: 안량·문추
A39: 38 | B39: ③ 관도 (200~207) | C39: 관도대전 | D39: 官渡之戰 | E39: =INDEX(칸!$I$2:$I$416,MATCH(A39,칸!$A$2:$A$416,1)) | F39: 관우는 안량과 문추를 단숨에 제압하고, 조조와 원소의 대결은 조조의 승리로 막을 내린다. | G39: 서기 200년, 원소의 십만 대군과 조조의 작은 군대가 관도에서 맞섰다. 관우가 백마에서 안량을 베고, 문추가 연진에서 쓰러졌으며, 조조는 끝내 오소를 불태워 북방의 패자가 되었다. | H39: =COUNTIF(칸!$A$2:$A$416,A39) | I39: =SUMIF(칸!$A$2:$A$416,A39,칸!$H$2:$H$416) | J39: =INDEX(비용표!$A$13:$A$17,MATCH(I39,비용표!$B$13:$B$17,1)) | K39: =INDEX(비용표!$C$13:$C$17,MATCH(I39,비용표!$B$13:$B$17,1)) | L39: 조조·관우 함께 참전, 적진에 안량·문추 시 관우 AT+0.5 | M39: 능력치 | N39: 관우 | O39: AT | P39: 0.5 | Q39: 조조·관우 | S39: 안량·문추
A40: 39 | B40: ③ 관도 (200~207) | C40: 오소 기습 | D40: 火燒烏巢 | E40: =INDEX(칸!$I$2:$I$416,MATCH(A40,칸!$A$2:$A$416,1)) | F40: 허유가 넘어오자 조조는 직접 오소의 군량고를 불태웠다. | G40: 관도의 대치가 길어지자 원소의 책사 허유가 조조에게 넘어와 오소의 군량고를 알렸다. 조조는 직접 오천 기를 이끌고 밤에 오소를 불태웠고, 지키던 순우경은 사로잡혔다. | H40: =COUNTIF(칸!$A$2:$A$416,A40) | I40: =SUMIF(칸!$A$2:$A$416,A40,칸!$H$2:$H$416) | J40: =INDEX(비용표!$A$13:$A$17,MATCH(I40,비용표!$B$13:$B$17,1)) | K40: =INDEX(비용표!$C$13:$C$17,MATCH(I40,비용표!$B$13:$B$17,1)) | L40: 최대 군량 +2 | M40: 도시 | P40: 2 | T40: grainCap
...

Sheet 한글 제목
A1: # | B1: 타이틀 | C1: 한글 제목
A2: 1 | B2: 도원결의 | C2: 도원결의
A3: 2 | B3: 황건적 토벌 | C3: 황건적 토벌
A4: 3 | B4: 온주참화웅 | C4: 술이 식기 전에
A5: 4 | B5: 호뢰관 삼영전여포 | C5: 세 영웅, 여포와 싸우다
A6: 5 | B6: 반동탁 연합군 | C6: 열여덟 제후, 동탁을 치다
A7: 6 | B7: 장안 천도 | C7: 불타는 낙양
A8: 7 | B8: 칠성보도 헌상 | C8: 조조, 동탁을 노리다
A9: 8 | B9: 진궁의 결별 | C9: 진궁, 조조를 떠나다
A10: 9 | B10: 형양의 추격 | C10: 조홍, 말을 내주다
A11: 10 | B11: 손견과 전국옥새 | C11: 우물 속의 옥새
A12: 11 | B12: 현산의 손견 | C12: 강동의 호랑이 지다
A13: 12 | B13: 백마의종 | C13: 흰 말의 기병대
... A118: 117 | B118: 형주의 유표 | C118: 두 아들 사이에서

Sheet 다국어
A1: # | B1: 타이틀 | C1: 제목_en | D1: 설명_en | E1: 상세_en | F1: 제목_ja | G1: 설명_ja | H1: 상세_ja | I1: 제목_zh_Hant | J1: 설명_zh_Hant | K1: 상세_zh_Hant | L1: 제목_zh_Hans | M1: 설명_zh_Hans | N1: 상세_zh_Hans | O1: 제목_pt_BR | P1: 설명_pt_BR | Q1: 상세_pt_BR | R1: 제목_pt_PT | S1: 설명_pt_PT | T1: 상세_pt_PT | U1: 제목_it | V1: 설명_it | W1: 상세_it | X1: 제목_es_419 | Y1: 설명_es_419 | Z1: 상세_es_419 | AA1: 제목_mn | AB1: 설명_mn | AC1: 상세_mn | AD1: 한자_zh_Hans
A2: 1 | B2: 도원결의 | C2: Oath of the Peach Garden | D2: Where the saga begins. Three men, it is said, swore brotherhood in a garden of peach trees. | E2: In the year the Yellow Turbans rose, Liu Bei, Guan Yu and Zhang Fei of Zhuo swore brotherhood in the peach orchard behind Zhang Fei's house. “We were not born on the same day, but we hope to die on the same day” — that oath bound the three for the rest of their lives. | F2: 桃園の誓い | G2: 三国志のはじまり。三人は桃の咲く庭で義兄弟の契りを結んだという。 | H2: 黄巾の乱が起きた年、涿県の劉備・関羽・張飛は、張飛の屋敷裏の桃園で義兄弟の契りを結んだ。同じ日に生まれることはできなかったが、同じ日に死なんことを願う――その誓いが三人の生涯を結びつけた。 | I2: 桃園三結義 | J2: 三國故事的開端。相傳三人在桃花盛開的園中結為異姓兄弟。 | K2: 黃巾起事那年，涿縣的劉備、關羽、張飛在張飛家後院的桃園結為兄弟。「不求同年同月同日生，但願同年同月同日死」，這句誓言繫住了三人的一生。 | L2: 桃园结义 | M2: 三国故事由此开始。相传三人在桃花园中结为异姓兄弟。 | N2: 黄巾起事那一年，涿县的刘备、关羽、张飞在张飞家后院的桃园中结为兄弟。「不求同年同月同日生，但求同年同月同日死」，这句誓言系住了三人的一生。 | O2: Juramento do Jardim de Pessegueiros | P2: O começo de tudo. Dizem que três homens se tornaram irmãos de juramento num jardim de pessegueiros. | Q2: No ano em que os Turbantes Amarelos se ergueram, Liu Bei, Guan Yu e Zhang Fei, de Zhuo, juraram irmandade no pomar de pessegueiros atrás da casa de Zhang Fei. Não nasceram no mesmo dia, mas desejaram morrer no mesmo dia — e esse juramento uniu os três pelo resto da vida. | R2: Juramento do Jardim dos Pessegueiros | S2: O início dos Três Reinos. Conta-se que três homens se juraram irmãos num jardim de pessegueiros. | T2: No ano em que os Turbantes Amarelos se levantaram, Liu Bei, Guan Yu e Zhang Fei, de Zhuoxian, juraram-se irmãos no pomar de pessegueiros atrás da casa de Zhang Fei. Não tinham nascido no mesmo dia, mas desejavam morrer no mesmo dia — e esse juramento uniu-os para toda a vida. | U2: Il giuramento del giardino dei peschi | V2: L'inizio dei Tre Regni. Si narra che tre uomini giurarono fratellanza in un giardino di peschi. | W2: Nell'anno in cui insorsero i Turbanti Gialli, a Zhuo, Liu Bei, Guan Yu e Zhang Fei si giurarono fratelli nel frutteto di peschi dietro la casa di Zhang Fei. «Non nati nello stesso giorno, ma uniti nel morire nello stesso giorno»: quel giuramento legò le loro vite per sempre. | X2: El juramento del jardín de melocotoneros | Y2: Aquí empieza la historia. Dicen que tres hombres se juraron hermanos en un jardín de melocotoneros. | Z2: El año en que se alzaron los Turbantes Amarillos, Liu Bei, Guan Yu y Zhang Fei, de Zhuo, se juraron hermanos en el huerto de melocotoneros detrás de la casa de Zhang Fei. «No nacimos el mismo día, pero deseamos morir el mismo día»: ese juramento ató a los tres para toda la vida. | AA2: Тоорын цэцэрлэгийн тангараг | AB2: Гурван улсын түүхийн эхлэл. Гурван эр тоорын цэцэрлэгт ах дүүс болохоор тангарагласан гэдэг. | AC2: Шар алчууртны бослого гарсан жил Чжосяний Лю Бэй, Гуань Юй, Чжан Фэй гурав Чжан Фэйн гэрийн арын тоорын цэцэрлэгт ах дүүсийн тангараг өргөв. «Нэг өдөр төрөөгүй ч нэг өдөр үхэхийг хүснэ» гэсэн тангараг гурвын насан туршийг холбосон юм. | AD2: 桃园结义
A3: 2 | B3: 황건적 토벌 | C3: Against the Yellow Turbans | D3: A rebellion raised by Zhang Jue of the Way of Great Peace. Three men who would one day divide the realm stood on the same battlefield. | E3: Zhang Jue, master of the Way of Great Peace, declared that “the Azure Heaven is already dead” and raised hundreds of thousands of followers. Among the imperial troops and volunteers sent against him were Liu Bei, Cao Cao and Sun Jian — the first battlefield of the men who would split the realm in three. | F3: 黄巾賊を討つ | G3: 太平道の張角が起こした乱。のちに天下を分ける三人が、同じ戦場に立った。 | H3: 太平道の教祖・張角が「蒼天すでに死す」と唱え、数十万の信徒を蜂起させた。討伐に出た官軍と義勇兵の中に、劉備・曹操・孫堅がいた――のちに天下を三つに分ける者たちの、最初の戦場である。 | I3: 討伐黃巾賊 | J3: 太平道張角掀起的大亂。日後三分天下的三人，站上了同一片戰場。 | K3: 太平道教主張角高喊「蒼天已死」，聚起數十萬信徒。前往討伐的官軍與義兵之中，有劉備、曹操、孫堅——這是日後三分天下之人的第一片戰場。 | L3: 讨伐黄巾贼 | M3: 太平道张角掀起的大乱。日后三分天下的三人，站上了同一片战场。 | N3: 太平道教主张角喊出「苍天已死」，聚起数十万信众。出征讨伐的官军与义兵之中，有刘备、曹操与孙坚——这是日后三分天下之人的第一战。 | O3: Contra os Turbantes Amarelos | P3: A revolta de Zhang Jiao, do Caminho da Grande Paz. Os três que um dia dividiriam o império lutaram no mesmo campo. | Q3: Zhang Jiao, mestre do Caminho da Grande Paz, proclamou que “o Céu Azul já está morto” e levantou centenas de milhares de fiéis. Entre as tropas imperiais e voluntários que marcharam contra ele estavam Liu Bei, Cao Cao e Sun Jian — o primeiro campo de batalha dos que dividiriam o império em três. | R3: Contra os Turbantes Amarelos | S3: A rebelião lançada por Zhang Jiao, do Caminho da Grande Paz. Os três que um dia dividiriam o império lutaram no mesmo campo de batalha. | T3: Zhang Jiao, mestre do Caminho da Grande Paz, proclamou «o Céu Azul já está morto» e levantou centenas de milhares de fiéis. Entre as tropas imperiais e os voluntários que os combateram estavam Liu Bei, Cao Cao e Sun Jian — o primeiro campo de batalha dos que um dia dividiriam o império em três. | U3: La rivolta dei Turbanti Gialli | V3: La rivolta scatenata da Zhang Jue della Via della Grande Pace. I tre che un giorno si sarebbero spartiti l'impero combatterono sullo stesso campo. | W3: Zhang Jue, capo della Via della Grande Pace, sollevò centinaia di migliaia di seguaci proclamando che «il Cielo Azzurro è già morto». Tra le truppe imperiali e i volontari accorsi a reprimerli c'erano Liu Bei, Cao Cao e Sun Jian: fu il primo campo di battaglia di coloro che avrebbero diviso l'impero in tre. | X3: Contra los Turbantes Amarillos | Y3: La rebelión de Zhang Jue, del Camino de la Gran Paz. Tres hombres que algún día dividirían el reino pisaron el mismo campo de batalla. | Z3: Zhang Jue, maestro del Camino de la Gran Paz, proclamó que «el Cielo Azul ya ha muerto» y levantó a cientos de miles de seguidores. Entre las tropas imperiales y los voluntarios enviados contra él estaban Liu Bei, Cao Cao y Sun Jian: el primer campo de batalla de quienes partirían el reino en tres. | AA3: Шар алчууртныг дарах нь | AB3: Тайпиндаогийн Чжан Цзюэгийн босгосон самуун. Хожим тэнгэрийн дорыг хуваах гурван эр нэг тулааны талбарт зогсов. | AC3: Тайпиндаогийн тэргүүн Чжан Цзюэ «Хөх тэнгэр аль хэдийн үхсэн» хэмээн хэдэн зуун мянган шүтэгчээ босгов. Дарахаар мордсон төрийн цэрэг ба сайн дурынхны дунд Лю Бэй, Цао Цао, Сунь Цзянь байв — хожим тэнгэрийн дорыг гурав хуваах эрсийн анхны тулаан энэ юм. | AD3: 讨黄巾贼
A4: 3 | B4: 온주참화웅 | C4: Before the Wine Grew Cold | D4: He returned with Hua Xiong's head before the warmed wine had cooled. | E4: Before Sishui Pass, Dong Zhuo's champion Hua Xiong cut down one allied officer after another, until Guan Yu, then a mere mounted archer, stepped forward. The Romance tells that he returned with Hua Xiong's head before the warm wine Cao Cao had poured for him had cooled. | F4: 酒が冷めぬうちに | G4: 温めた酒が冷めぬうちに、華雄の首を斬って戻った。 | H4: 汜水関の前で董卓の猛将・華雄が連合軍の将を次々と斬ると、一介の馬弓手にすぎなかった関羽が名乗り出た。曹操が注いだ温かい酒が冷めぬうちに、関羽は華雄の首を提げて戻ったと演義は伝える。 | I4: 酒尚溫時 | J4: 溫好的酒還沒涼，華雄的首級已被提了回來。 | K4: 汜水關前，董卓的猛將華雄接連斬殺聯軍將領，此時身為馬弓手的關羽挺身而出。演義說，曹操斟給他的熱酒尚未變涼，關羽已提著華雄的首級歸來。 | L4: 酒尚温时 | M4: 热酒还未凉，华雄的首级已被提了回来。 | N4: 汜水关前，董卓猛将华雄接连斩杀联军诸将，区区马弓手关羽挺身而出。演义说，曹操斟下的热酒尚未凉，关羽已提着华雄的首级回来了。 | O4: Antes que o Vinho Esfrie | P4: Voltou com a cabeça de Hua Xiong antes que o vinho quente esfriasse. | Q4: Diante do Passo de Sishui, Hua Xiong, o feroz general de Dong Zhuo, abatia um a um os campeões da coalizão, até que Guan Yu, então simples arqueiro montado, se apresentou. Conta o Romance que ele voltou com a cabeça de Hua Xiong antes que esfriasse o vinho quente que Cao Cao lhe servira. | R4: Antes que o Vinho Arrefeça | S4: Voltou com a cabeça de Hua Xiong antes que o vinho aquecido arrefecesse. | T4: Diante da Passagem de Sishui, o feroz Hua Xiong, de Dong Zhuo, abatia um a um os generais da coligação, até que Guan Yu, então simples arqueiro a cavalo, se ofereceu. Segundo o Romance, regressou com a cabeça de Hua Xiong antes que arrefecesse o vinho quente que Cao Cao lhe servira. | U4: Prima che il vino si raffreddi | V4: Tornò con la testa di Hua Xiong prima che il vino caldo si raffreddasse. | W4: Davanti al passo di Sishui, Hua Xiong, feroce generale di Dong Zhuo, abbatteva uno dopo l'altro i campioni della coalizione; allora si fece avanti Guan Yu, semplice arciere a cavallo. Il Romanzo narra che tornò con la testa di Hua Xiong prima ancora che il vino caldo versatogli da Cao Cao si raffreddasse. | X4: Antes de que se enfríe el vino | Y4: Volvió con la cabeza de Hua Xiong antes de que se enfriara el vino caliente. | Z4: Frente al paso de Sishui, Hua Xiong, el campeón de Dong Zhuo, abatía a un oficial aliado tras otro, hasta que dio un paso al frente Guan Yu, entonces un simple arquero montado. La novela cuenta que volvió con la cabeza de Hua Xiong antes de que se enfriara el vino que Cao Cao le había servido. | AA4: Дарс хөрөхөөс өмнө | AB4: Халаасан дарс хөрөхөөс өмнө Хуа Сюны толгойг авч ирэв. | AC4: Сышуй хаалганы өмнө Дун Чжогийн баатар Хуа Сюн холбоотны жанждыг ар араас нь цавчихад, ердийн морьт харваач байсан Гуань Юй гарч ирэв. Цао Цаогийн хийж өгсөн халуун дарс хөрөөгүй байхад Гуань Юй Хуа Сюны толгойг бариад буцаж ирсэн хэмээн туужид өгүүлдэг. | AD4: 温酒斩华雄
A5: 4 | B5: 호뢰관 삼영전여포 | C5: Three Heroes Fight Lü Bu | D5: Only when all three brothers charged together was Lü Bu driven back. | E5: When no one could stand against Lü Bu at Hulao Pass, Zhang Fei rode out to meet him, and Guan Yu and Liu Bei joined the fight one after the other. Only against all three at once did Lü Bu turn his horse — the greatest duel the Romance ever painted. | F5: 三英、呂布と戦う | G5: 三兄弟がそろってかかり、ようやく呂布を退けた。 | H5: 虎牢関に出た呂布に敵う者がなく、まず張飛が打ちかかり、関羽と劉備が次々と加わった。三人が一斉にかかってようやく呂布は馬首を返した――演義が描いた三国随一の一騎打ちである。 | I5: 三英戰呂布 | J5: 三兄弟一起上陣，才逼退了呂布。 | K5: 虎牢關前無人能擋呂布，張飛率先迎戰，關羽與劉備相繼加入。直到三人一齊圍攻，呂布才撥轉馬頭——這是演義描繪的三國第一單挑。 | L5: 三英战吕布 | M5: 三兄弟一齐上阵，才把吕布逼退。 | N5: 虎牢关前吕布无人能敌，张飞率先迎战，关羽、刘备相继杀入。三人合力夹攻，吕布才拨转马头——这是演义描绘的三国第一单挑。 | O5: Três Heróis Contra Lü Bu | P5: Só os três irmãos juntos conseguiram fazer Lü Bu recuar. | Q5: Ninguém resistia a Lü Bu diante do Passo de Hulao, até que Zhang Fei o enfrentou, e Guan Yu e Liu Bei entraram na luta em seguida. Só com os três atacando ao mesmo tempo Lü Bu virou o cavalo — o maior duelo dos Três Reinos, como o Romance o pinta. | R5: Três Heróis Contra Lü Bu | S5: Só os três irmãos juntos conseguiram fazer Lü Bu recuar. | T5: Ninguém resistia a Lü Bu à frente da Passagem de Hulao, até que Zhang Fei o enfrentou, e Guan Yu e Liu Bei se lançaram a seguir. Só com os três ao mesmo tempo Lü Bu fez dar meia-volta ao cavalo — o maior duelo dos Três Reinos, tal como o Romance o pinta. | U5: Tre eroi contro Lü Bu | V5: Solo assalendolo tutti e tre insieme i fratelli riuscirono a respingere Lü Bu. | W5: Al passo di Hulao nessuno reggeva il confronto con Lü Bu; si fece avanti Zhang Fei, poi intervennero Guan Yu e infine Liu Bei. Solo quando i tre lo attaccarono insieme Lü Bu voltò il cavallo: è il duello più celebre che il Romanzo abbia narrato. | X5: Tres héroes contra Lü Bu | Y5: Solo cuando los tres hermanos atacaron juntos retrocedió Lü Bu. | Z5: Nadie podía resistir a Lü Bu en el paso de Hulao, hasta que Zhang Fei lo enfrentó, y luego Guan Yu y Liu Bei se lanzaron uno tras otro. Solo ante los tres a la vez dio Lü Bu media vuelta a su caballo: el duelo más grande que pintó la novela. | AA5: Гурван баатар ба Люй Бу | AB5: Гурван ах дүү хамтдаа дайрч байж л Люй Буг ухрааж чадав. | AC5: Хулао хаалганд гарсан Люй Бутай хэн ч тэнцэхгүй байхад Чжан Фэй түрүүлж тулж, Гуань Юй, Лю Бэй ээлжлэн орж ирэв. Гурвуулаа нэгэн зэрэг дайрч байж л Люй Бу морийнхоо толгойг эргүүлэв — туужийн дүрсэлсэн Гурван улсын хамгийн гайхамшигт ганцаарчилсан тулаан. | AD5: 虎牢关三英战吕布
A6: 5 | B6: 반동탁 연합군 | C6: Eighteen Lords Against Dong Zhuo | D6: Eighteen lords gathered to march on Luoyang, with Yuan Shao as their leader. | E6: When Dong Zhuo deposed the emperor, the lords east of the passes raised their armies and named Yuan Shao their leader. But each watched the others and none would advance, and the alliance broke apart quarrelling over glory. | F6: 十八諸侯、董卓を討つ | G6: 十八の諸侯が洛陽を目指して集い、盟主には袁紹が立った。 | H6: 董卓が皇帝を廃立すると、関東の諸侯が兵を挙げ、袁紹を盟主に推した。だが諸侯は互いに牽制して進まず、連合は功を争ううちに散り散りになった。 | I6: 十八路諸侯討董卓 | J6: 十八路諸侯向洛陽集結，盟主是袁紹。 | K6: 董卓廢立天子，關東諸侯起兵，推袁紹為盟主。然而諸侯彼此牽制、按兵不動，聯軍在爭功之中終於離散。 | L6: 十八路诸侯讨董卓 | M6: 十八路诸侯向洛阳会集，盟主是袁绍。 | N6: 董卓废立天子，关东诸侯起兵，推袁绍为盟主。然而诸侯彼此牵制、按兵不进，联盟在争功中四散。 | O6: Dezoito Senhores Contra Dong Zhuo | P6: Dezoito senhores marcharam rumo a Luoyang, e o líder da aliança era Yuan Shao. | Q6: Quando Dong Zhuo trocou o imperador a seu bel-prazer, os senhores do leste ergueram exércitos e fizeram de Yuan Shao seu líder. Mas vigiavam uns aos outros e não avançavam, e a aliança se desfez disputando os méritos. | R6: Dezoito Senhores Contra Dong Zhuo | S6: Dezoito senhores marcharam sobre Luoyang, com Yuan Shao à cabeça da aliança. | T6: Quando Dong Zhuo depôs o imperador, os senhores a leste dos desfiladeiros ergueram exércitos e fizeram de Yuan Shao o líder da aliança. Mas vigiavam-se uns aos outros e não avançavam, e a coligação desfez-se a disputar glórias. | U6: Diciotto signori contro Dong Zhuo | V6: Diciotto signori marciarono su Luoyang, con Yuan Shao a capo dell'alleanza. | W6: Quando Dong Zhuo depose l'imperatore, i signori a est dei passi levarono le armi e scelsero Yuan Shao come capo della coalizione. Ma i signori si sorvegliavano l'un l'altro senza avanzare, e l'alleanza si sciolse tra le contese per la gloria. | X6: Dieciocho señores contra Dong Zhuo | Y6: Dieciocho señores marcharon hacia Luoyang, con Yuan Shao al frente de la alianza. | Z6: Cuando Dong Zhuo depuso al emperador, los señores del este alzaron sus ejércitos y nombraron a Yuan Shao jefe de la alianza. Pero se vigilaban unos a otros y no avanzaban; la coalición se disolvió disputándose los méritos. | AA6: Дун Чжогийн эсрэг 18 ван | AB6: Арван найман ноён Лоян руу чиглэн цугларч, Юань Шао тэргүүн болов. | AC6: Дун Чжо хааныг сольж тавихад Гуандуны ноёд цэрэг босгож, Юань Шаог холбооны тэргүүнээр өргөмжлөв. Гэвч ноёд бие биенээ хардан урагшилсангүй, холбоо гавьяа булаалдсаар тарж бутрав. | AD6: 反董卓联合军
A7: 6 | B7: 장안 천도 | C7: Luoyang in Flames | D7: Dong Zhuo burned Luoyang and dragged the emperor and the people off to Chang'an. | E7: Pressed by the allied armies, Dong Zhuo set fire to the palaces and homes of Luoyang and drove the emperor and millions of people to Chang'an. Countless fell along the road, and Luoyang was left in ruins. | F7: 燃える洛陽 | G7: 董卓は洛陽を焼き払い、皇帝と民を長安へ連れ去った。 | H7: 連合軍に押された董卓は洛陽の宮殿と民家を焼き払い、皇帝と数百万の民を長安へ引き連れていった。道に倒れた民は数知れず、洛陽は廃墟となった。 | I7: 焚燒的洛陽 | J7: 董卓焚毀洛陽，挾天子與百姓西遷長安。 | K7: 被聯軍逼退的董卓燒盡洛陽的宮殿與民宅，驅趕天子和數百萬百姓前往長安。倒斃路旁的百姓不計其數，洛陽化為一片廢墟。 | L7: 燃烧的洛阳 | M7: 董卓焚毁洛阳，把天子与百姓驱往长安。 | N7: 被联军逼退的董卓焚烧洛阳宫室民宅，挟天子、驱百姓数百万西迁长安。倒毙道旁的百姓不可胜数，洛阳化为一片废墟。 | O7: Luoyang em Chamas | P7: Dong Zhuo incendiou Luoyang e arrastou o imperador e o povo para Chang'an. | Q7: Pressionado pela coalizão, Dong Zhuo queimou os palácios e as casas de Luoyang e arrastou o imperador e milhões de pessoas para Chang'an. Incontáveis caíram pelo caminho, e Luoyang virou ruínas. | R7: Luoyang em Chamas | S7: Dong Zhuo incendiou Luoyang e arrastou o imperador e o povo para Chang'an. | T7: Pressionado pela coligação, Dong Zhuo pegou fogo aos palácios e às casas de Luoyang e arrastou o imperador e milhões de pessoas para Chang'an. Incontáveis caíram pelo caminho, e Luoyang ficou em ruínas. | U7: Luoyang in fiamme | V7: Dong Zhuo diede fuoco a Luoyang e trascinò l'imperatore e il popolo a Chang'an. | W7: Incalzato dalla coalizione, Dong Zhuo incendiò i palazzi e le case di Luoyang e trascinò l'imperatore e milioni di sudditi verso Chang'an. Innumerevoli caddero lungo la strada, e Luoyang divenne un cumulo di rovine. | X7: Luoyang en llamas | Y7: Dong Zhuo quemó Luoyang y arrastró al emperador y al pueblo hasta Chang'an. | Z7: Acosado por la alianza, Dong Zhuo incendió los palacios y las casas de Luoyang y arrastró al emperador y a millones de personas hacia Chang'an. Incontables cayeron por el camino, y Luoyang quedó en ruinas. | AA7: Шатаж буй Лоян | AB7: Дун Чжо Лояныг шатааж, хаан болон ард түмнийг Чанъань руу хөөн авав. | AC7: Холбоотны цэрэгт шахагдсан Дун Чжо Лояны ордон, айл өрхийг галдан шатааж, хаан ба хэдэн сая ардыг Чанъань руу хөөн туув. Замдаа унасан ард тоолшгүй олон байсан бөгөөд Лоян эзгүй балгас болжээ. | AD7: 长安迁都
A8: 7 | B8: 칠성보도 헌상 | C8: Cao Cao's Blade for Dong Zhuo | D8: The blade meant to stab Dong Zhuo became a gift the moment it was seen. | E8: With the Seven Star Sword borrowed from Wang Yun, Cao Cao drew steel in Dong Zhuo's bedchamber — but Dong Zhuo saw him in the mirror and turned. Cao Cao knelt, claiming he had come to present the sword, and fled Luoyang that very day. | F8: 曹操、董卓を狙う | G8: 董卓を刺すはずの刀は、見破られた瞬間に献上品となった。 | H8: 王允から七星宝刀を借りた曹操は董卓の寝所で刀を抜いたが、鏡に映った姿に董卓が振り返った。曹操は刀を献上しに来たと膝をつき、その足で洛陽を逃れた。 | I8: 曹操欲刺董卓 | J8: 本要刺向董卓的刀，在被識破的一瞬成了獻禮。 | K8: 曹操向王允借來七星寶刀，在董卓寢室中拔刀，卻被鏡中的身影驚動了董卓。曹操當即跪下，說是前來獻刀，隨後便逃出了洛陽。 | L8: 曹操刺董卓 | M8: 本要刺向董卓的刀，在败露的一刻成了献礼。 | N8: 曹操向王允借来七星宝刀，在董卓卧房中拔刀，镜中倒影却让董卓回过头来。曹操当即跪下称是来献刀，随即逃出洛阳。 | O8: Cao Cao Mira Dong Zhuo | P8: A espada que devia matar Dong Zhuo virou presente no instante em que foi vista. | Q8: Com a Espada das Sete Estrelas emprestada de Wang Yun, Cao Cao a desembainhou no quarto de Dong Zhuo, mas este o viu refletido no espelho e se virou. Cao Cao ajoelhou-se dizendo que viera oferecer a espada, e fugiu de Luoyang naquele mesmo instante. | R8: Cao Cao Atenta Contra Dong Zhuo | S8: A espada destinada a Dong Zhuo tornou-se oferenda no instante em que foi descoberta. | T8: Com a Espada das Sete Estrelas emprestada por Wang Yun, Cao Cao desembainhou-a nos aposentos de Dong Zhuo, mas este viu o seu reflexo no espelho e voltou-se. Cao Cao ajoelhou-se, dizendo que viera oferecer a espada, e fugiu logo de Luoyang. | U8: Cao Cao punta su Dong Zhuo | V8: Il pugnale destinato a Dong Zhuo, nell'istante in cui fu scoperto, divenne un dono. | W8: Con la Spada delle Sette Stelle avuta da Wang Yun, Cao Cao la sguainò nella camera di Dong Zhuo, ma questi si voltò vedendone il riflesso nello specchio. Cao Cao si inginocchiò dicendo di essere venuto a offrirgli la spada, e quella stessa notte fuggì da Luoyang. | X8: Cao Cao apunta a Dong Zhuo | Y8: El sable destinado a Dong Zhuo se volvió un regalo en el instante en que lo descubrieron. | Z8: Con el sable de las Siete Estrellas que le prestó Wang Yun, Cao Cao desenvainó en la alcoba de Dong Zhuo, pero este vio su reflejo en un espejo y se volvió. Cao Cao se arrodilló diciendo que venía a ofrecerle el sable, y esa misma noche huyó de Luoyang. | AA8: Цао Цао Дун Чжог онилов | AB8: Дун Чжог хатгах гэсэн илд илрэх агшинд бэлэг болон хувирав. | AC8: Ван Юнээс Долоон одны эрдэнэт илдийг зээлсэн Цао Цао Дун Чжогийн унтлагын өрөөнд илдээ сугалсан ч, толинд тусах дүрийг хараад Дун Чжо эргэн харав. Цао Цао илдийг бэлэглэхээр ирлээ хэмээн өвдөг сөгдөөд, тэр дороо Лояныг орхин зугтав. | AD8: 献七星宝刀
A9: 8 | B9: 진궁의 결별 | C9: Chen Gong Leaves Cao Cao | D9: “Better that I betray the world” — that night, Chen Gong left Cao Cao. | E9: The magistrate Chen Gong freed Cao Cao as he fled Dong Zhuo and set out on the road with him. But when Cao Cao killed Lü Boshe's household over a misunderstanding and said, “Better that I betray the world,” Chen Gong left him that same night. | F9: 陳宮、曹操と決別す | G9: 「我、天下の人に背くとも」――陳宮はその夜、曹操のもとを去った。 | H9: 董卓から逃れる曹操を県令の陳宮が見逃し、ともに旅立った。だが誤解から呂伯奢の一家を殺してなお「我が天下の人に背くとも」と言い放つ曹操を見て、陳宮はその夜のうちに去った。 | I9: 陳宮離曹而去 | J9: 「寧教我負天下人」——陳宮當夜離開了曹操。 | K9: 縣令陳宮放走逃避董卓追捕的曹操，與他同行。但曹操因誤會殺了呂伯奢一家，還說「寧教我負天下人」，陳宮便在當夜離去。 | L9: 陈宫离去 | M9: 「宁我负天下人」——陈宫在那一夜离开了曹操。 | N9: 县令陈宫放走逃避董卓的曹操，与他一同上路。可曹操误杀吕伯奢一家后仍说「宁我负天下人」，陈宫当夜便弃他而去。 | O9: Chen Gong Deixa Cao Cao | P9: “Prefiro trair o mundo” — naquela noite, Chen Gong deixou Cao Cao. | Q9: Chen Gong, magistrado do condado, libertou Cao Cao, que fugia de Dong Zhuo, e partiu com ele. Mas ao ver Cao Cao matar por engano a família de Lü Boshe e ainda dizer “prefiro trair o mundo”, Chen Gong o abandonou naquela mesma noite. | R9: Chen Gong Abandona Cao Cao | S9: «Prefiro trair o mundo» — nessa noite, Chen Gong deixou Cao Cao. | T9: O magistrado Chen Gong libertou Cao Cao, que fugia de Dong Zhuo, e partiu com ele. Mas ao ver Cao Cao matar por engano a família de Lü Boshe e ainda dizer «prefiro trair o mundo», Chen Gong foi-se embora nessa mesma noite. | U9: Chen Gong lascia Cao Cao | V9: «Meglio che sia io a tradire il mondo»: quella notte Chen Gong abbandonò Cao Cao. | W9: Il magistrato Chen Gong liberò Cao Cao in fuga da Dong Zhuo e partì con lui. Ma quando Cao Cao, dopo aver sterminato per errore la famiglia di Lü Boshe, disse «meglio che sia io a tradire il mondo», Chen Gong se ne andò quella notte stessa. | X9: Chen Gong deja a Cao Cao | Y9: «Prefiero traicionar yo al mundo» — esa misma noche, Chen Gong abandonó a Cao Cao. | Z9: Cuando Cao Cao huía de Dong Zhuo, el magistrado Chen Gong lo liberó y partió con él. Pero al ver que, tras matar por error a la familia de Lü Boshe, Cao Cao decía «prefiero traicionar yo al mundo», Chen Gong se marchó esa misma noche. | AA9: Чэнь Гун Цао Цаогоос салав | AB9: «Тэнгэрийн дорыг би орхих нь дээр» — Чэнь Гун тэр шөнө Цао Цаогоос салан одов. | AC9: Дун Чжогоос зугтаж явсан Цао Цаог шянь захирагч Чэнь Гун суллаад хамт замд гарав. Гэвч Люй Бошэгийн гэр бүлийг буруу ойлголтоор хөнөөчхөөд «Тэнгэрийн дорыг би орхих нь дээр» гэж хэлсэн Цао Цаог хараад Чэнь Гун тэр шөнөдөө явжээ. | AD9: 陈宫决别
A10: 9 | B10: 형양의 추격 | C10: Cao Hong Gives His Horse | D10: “The realm can do without Cao Hong, but not without you.” — Cao Hong gave up his own horse. | E10: Alone among the allies, Cao Cao pursued Dong Zhuo and was badly beaten by Xu Rong at Xingyang. When he fell without a horse, Cao Hong gave him his own, saying, “The realm can do without Cao Hong, but not without you.” | F10: 曹洪、馬を譲る | G10: 「天下に曹洪なかるべきも、君なかるべからず」――曹洪は自らの馬を差し出した。 | H10: 連合軍でただ一人董卓を追った曹操は、滎陽で徐栄に大敗した。馬を失って倒れた曹操に、曹洪は自らの馬を差し出し「天下に曹洪なかるべきも、君なかるべからず」と言った。 | I10: 曹洪讓馬 | J10: 「天下可無曹洪，不可無公。」——曹洪讓出了自己的馬。 | K10: 聯軍之中唯有曹操獨自追擊董卓，卻在滎陽大敗於徐榮。曹操失馬倒地，曹洪把自己的馬讓給他，說：「天下可無曹洪，不可無公。」 | L10: 曹洪让马 | M10: 「天下可无洪，不可无公。」——曹洪让出了自己的马。 | N10: 联军中唯有曹操独自追击董卓，却在荥阳大败于徐荣。失马倒地的曹操面前，曹洪让出坐骑，说道：「天下可无洪，不可无公。」 | O10: Cao Hong Cede seu Cavalo | P10: “O mundo pode viver sem Cao Hong, mas não sem o senhor.” — e Cao Hong lhe deu o próprio cavalo. | Q10: O único da coalizão a perseguir Dong Zhuo, Cao Cao sofreu dura derrota para Xu Rong em Xingyang. Caído e sem montaria, ouviu Cao Hong dizer, oferecendo-lhe o próprio cavalo: “O mundo pode viver sem Cao Hong, mas não sem o senhor.” | R10: Cao Hong Cede o Cavalo | S10: «O mundo passa sem Cao Hong, mas não sem vós.» — Cao Hong deu-lhe o seu cavalo. | T10: Único da coligação a perseguir Dong Zhuo, Cao Cao foi duramente derrotado por Xu Rong em Xingyang. Caído e sem montada, recebeu de Cao Hong o seu próprio cavalo: «O mundo passa sem Cao Hong, mas não sem vós.» | U10: Cao Hong cede il suo cavallo | V10: «Il mondo può fare a meno di Cao Hong, ma non di voi.» E Cao Hong gli cedette il suo cavallo. | W10: Unico della coalizione a inseguire Dong Zhuo, Cao Cao fu duramente sconfitto da Xu Rong a Xingyang. A Cao Cao, caduto e senza cavallo, Cao Hong diede il proprio dicendo: «Il mondo può fare a meno di Cao Hong, ma non di voi». | X10: Cao Hong cede su caballo | Y10: «El mundo puede pasar sin Cao Hong, pero no sin usted, señor» — y Cao Hong le dio su caballo. | Z10: Solo entre los aliados, Cao Cao persiguió a Dong Zhuo y fue derrotado por Xu Rong en Xingyang. Al verlo caído y sin montura, Cao Hong le cedió su caballo: «El mundo puede pasar sin Cao Hong, pero no sin usted, señor». | AA10: Цао Хун морио өгөв | AB10: «Тэнгэрийн дор Цао Хунгүй байж болно, харин таныг үгүйлж болохгүй» — Цао Хун морио өгөв. | AC10: Холбоотнуудаас ганцаараа Дун Чжог мөрдсөн Цао Цао Синъянд Сюй Жунд бут ниргүүлэв. Мориноосоо салж унасан Цао Цаод Цао Хун өөрийн морио өгөхдөө «Тэнгэрийн дор Цао Хунгүй байж болно, харин таныг үгүйлж болохгүй» гэжээ. | AD10: 荥阳追击
A11: 10 | B11: 손견과 전국옥새 | C11: The Seal in the Well | D11: The imperial seal, drawn up from a well in burnt Luoyang. | E11: First into the burned city of Luoyang, Sun Jian drew the imperial seal out of a palace well. Hiding it as he set off home to Jiangdong, he made enemies of Yuan Shao and Liu Biao. | F11: 井戸の中の玉璽 | G11: 焼け落ちた洛陽の井戸から引き上げられた、皇帝の玉璽。 | H11: 焼けた洛陽に一番乗りした孫堅は、宮中の井戸から皇帝の玉璽を拾い上げた。玉璽を隠したまま江東へ帰ろうとした孫堅は、袁紹・劉表と仇敵になった。 | I11: 井中玉璽 | J11: 從焚毀的洛陽井中撈起的傳國玉璽。 | K11: 孫堅率先進入焚毀的洛陽，在宮中井裡撈出了傳國玉璽。他藏起玉璽打算回江東，從此與袁紹、劉表結下了仇怨。 | L11: 井中玉玺 | M11: 从焚毁的洛阳井中捞起的传国玉玺。 | N11: 孙坚率先进入焚毁的洛阳，在宫中井里捞起了天子玉玺。他私藏玉玺欲回江东，从此与袁绍、刘表结下仇怨。 | O11: O Selo no Fundo do Poço | P11: O selo imperial, retirado de um poço na Luoyang incendiada. | Q11: Primeiro a entrar na Luoyang em cinzas, Sun Jian tirou o selo imperial de um poço do palácio. Escondendo-o para voltar a Jiangdong, ele se tornou inimigo de Yuan Shao e Liu Biao. | R11: O Selo no Fundo do Poço | S11: O selo imperial, retirado de um poço da Luoyang incendiada. | T11: Primeiro a entrar na Luoyang queimada, Sun Jian tirou o selo imperial de um poço do palácio. Escondeu-o e quis regressar a Jiangdong, o que fez de Yuan Shao e de Liu Biao seus inimigos. | U11: Il sigillo nel pozzo | V11: Il sigillo imperiale ripescato da un pozzo di Luoyang in fiamme. | W11: Primo a entrare nella Luoyang bruciata, Sun Jian ripescò il sigillo imperiale da un pozzo del palazzo. Mentre cercava di tornare a Jiangdong tenendolo nascosto, si inimicò Yuan Shao e Liu Biao. | X11: El sello en el fondo del pozo | Y11: El sello imperial, rescatado de un pozo en la Luoyang incendiada. | Z11: El primero en entrar en la Luoyang incendiada fue Sun Jian, que sacó el sello imperial de un pozo del palacio. Por ocultarlo y querer volver con él a Jiangdong, se ganó la enemistad de Yuan Shao y Liu Biao. | AA11: Худгийн ёроол дахь тамга | AB11: Шатсан Лояны худгаас гаргаж авсан хааны хаш тамга. | AC11: Шатсан Лоянд түрүүлж орсон Сунь Цзянь ордны худгаас хааны хаш тамгыг олж гаргав. Тамгыг нууж Цзяндун руу буцахаар зэхсэн Сунь Цзянь Юань Шао, Лю Бяо хоёртой өстөн болжээ. | AD11: 孙坚得玉玺
A12: 11 | B12: 현산의 손견 | C12: The Tiger of Jiangdong Falls | D12: The Tiger of Jiangdong fell at Mount Xian, caught in Kuai Yue's ambush. | E12: Sent by Yuan Shu against Jing Province, Sun Jian drove hard against Liu Biao's general Huang Zu. But by Kuai Yue's plan, hidden troops on Mount Xian struck him with stones and arrows, and the Tiger of Jiangdong fell at thirty-seven. | F12: 江東の虎、斃れる | G12: 江東の虎は蒯越の伏兵にかかり、峴山に斃れた。 | H12: 袁術の命で荊州を攻めた孫堅は、劉表の将・黄祖を追い詰めた。だが蒯越の計で峴山に潜んだ伏兵から石と矢を浴び、江東の虎は三十七歳で斃れた。 | I12: 江東之虎殞落 | J12: 江東之虎中了蒯越的埋伏，倒在峴山。 | K12: 孫堅奉袁術之命攻打荊州，將劉表部將黃祖逼入絕境。然而蒯越設計，伏兵藏於峴山，以亂石箭矢擊中孫堅，江東之虎三十七歲便殞落了。 | L12: 江东猛虎陨落 | M12: 江东猛虎中了蒯越的埋伏，倒在岘山。 | N12: 孙坚奉袁术之命攻荆州，将刘表部将黄祖逼入绝境。但蒯越设计在岘山埋下伏兵，乱石与箭雨之下，江东猛虎陨落，年仅三十七。 | O12: Cai o Tigre de Jiangdong | P12: O Tigre de Jiangdong caiu no monte Xian, na emboscada de Kuai Yue. | Q12: Por ordem de Yuan Shu, Sun Jian atacou Jing e encurralou Huang Zu, general de Liu Biao. Mas, pelo plano de Kuai Yue, tropas escondidas no monte Xian o cobriram de pedras e flechas, e o Tigre de Jiangdong caiu aos trinta e sete anos. | R12: Cai o Tigre de Jiangdong | S12: O Tigre de Jiangdong caiu no monte Xian, na emboscada de Kuai Yue. | T12: Por ordem de Yuan Shu, Sun Jian atacou Jingzhou e encurralou Huang Zu, general de Liu Biao. Mas, por um ardil de Kuai Yue, uma emboscada no monte Xian cobriu-o de pedras e flechas, e o Tigre de Jiangdong tombou aos trinta e sete anos. | U12: Cade la Tigre di Jiangdong | V12: La Tigre di Jiangdong cadde sul monte Xian nell'imboscata di Kuai Yue. | W12: Per ordine di Yuan Shu, Sun Jian attaccò Jingzhou e incalzò Huang Zu, generale di Liu Biao. Ma, secondo il piano di Kuai Yue, i soldati nascosti sul monte Xian lo colpirono con pietre e frecce, e la Tigre di Jiangdong cadde a trentasette anni. | X12: Cae el Tigre de Jiangdong | Y12: El Tigre de Jiangdong cayó en el monte Xian, en la emboscada de Kuai Yue. | Z12: Por orden de Yuan Shu, Sun Jian atacó Jing y acorraló a Huang Zu, general de Liu Biao. Pero, por el plan de Kuai Yue, una emboscada oculta en el monte Xian lo cubrió de piedras y flechas, y el Tigre de Jiangdong cayó a los treinta y siete años. | AA12: Цзяндуны бар унав | AB12: Цзяндуны бар Куай Юэгийн отолтод өртөж Сяньшаньд унав. | AC12: Юань Шугийн тушаалаар Цзинчжоуг довтолсон Сунь Цзянь Лю Бяогийн жанжин Хуан Цзуг шахаж байв. Гэвч Куай Юэгийн заль ёсоор Сяньшаньд нуугдсан отолтынхны чулуу, суманд өртөж, Цзяндуны бар гучин долоон насандаа унажээ. | AD12: 岘山伏兵
A13: 12 | B13: 백마의종 | C13: The White Horse Riders | D13: Gongsun Zan's cavalry rode only white horses, and even the frontier tribes feared them. | E13: Gongsun Zan chose thousands of expert mounted archers on white horses and called them the “White Horse Volunteers.” It is said the Wuhuan of the north fled at the mere sight of white horses, so the name alone guarded the frontier. | F13: 白馬の騎兵隊 | G13: 白馬ばかりを選んで乗る公孫瓚の騎兵隊は、異民族にも恐れられた。 | H13: 公孫瓚は白馬に乗る弓の名手数千を選び、「白馬義従」と呼んだ。北方の烏桓は白馬を見ただけで逃げ出したといい、その名だけで辺境を守った。 | I13: 白馬騎兵 | J13: 公孫瓚專騎白馬的騎兵，連異族都為之畏懼。 | K13: 公孫瓚挑選數千名善射、騎白馬的騎兵，號為「白馬義從」。據說北方的烏桓一見白馬便逃，單憑這個名號就守住了邊境。 | L13: 白马骑兵 | M13: 专骑白马的公孙瓒骑兵，连异族也闻风丧胆。 | N13: 公孙瓒挑选骑白马、善骑射者数千人，号为「白马义从」。北方乌桓一见白马便逃，单凭这个名号就能守住边境。 | O13: A Cavalaria dos Cavalos Brancos | P13: A cavalaria de Gongsun Zan, montada só em cavalos brancos, era temida até pelos povos do norte. | Q13: Gongsun Zan escolheu milhares de arqueiros montados em cavalos brancos e os chamou de “Cavaleiros Leais do Cavalo Branco”. Dizem que os Wuhuan do norte fugiam só de ver um cavalo branco — o nome bastava para guardar a fronteira. | R13: Os Cavaleiros dos Cavalos Brancos | S13: A cavalaria de Gongsun Zan, toda montada em cavalos brancos, era temida pelos povos da fronteira. | T13: Gongsun Zan escolheu milhares de arqueiros a cavalo montados em cavalos brancos e chamou-lhes os Leais dos Cavalos Brancos. Diz-se que os Wuhuan do norte fugiam só de ver um cavalo branco, e esse nome bastava para guardar a fronteira. | U13: La cavalleria dai cavalli bianchi | V13: Persino i barbari temevano la cavalleria di Gongsun Zan, che montava solo cavalli bianchi. | W13: Gongsun Zan scelse migliaia di abili arcieri a cavallo su destrieri bianchi e li chiamò «I Fedeli dai Cavalli Bianchi». Si dice che i Wuhuan del nord fuggissero alla sola vista di un cavallo bianco: quel nome bastava a difendere la frontiera. | X13: Los jinetes del caballo blanco | Y13: Hasta los pueblos bárbaros temían a los jinetes de Gongsun Zan, montados solo en caballos blancos. | Z13: Gongsun Zan escogió a miles de arqueros a caballo sobre monturas blancas y los llamó los «Jinetes Leales del Caballo Blanco». Se dice que los wuhuan del norte huían con solo ver un caballo blanco: aquel nombre bastaba para guardar la frontera. | AA13: Цагаан морьт хүлэг цэрэг | AB13: Зөвхөн цагаан морь унасан Гунсунь Цзаны хүлэг цэргээс харь үндэстэн хүртэл эмээдэг байв. | AC13: Гунсунь Цзань цагаан морь унасан мэргэн харваач хэдэн мянган хүлэг цэрэг шилж, «Цагаан морьт үнэнч дагалдагсад» хэмээн нэрлэв. Хойд зүгийн Ухуань цагаан морь харангуутаа зугтдаг байсан гэдэг тул тэр нэрээр л хил хязгаарыг сахиж байжээ. | AD13: 白马义从
... A118: 117 | B118: 형주의 유표 | C118: Torn Between Two Sons | D118: Liu Biao, one of the Eight Talents, held Jing Province but wavered between his two sons. | E118: Liu Biao was a renowned scholar counted among the Eight Talents, and he made Jing Province a refuge in an age of chaos. But he could not choose an heir between his eldest son Liu Qi and his second son Liu Cong, and after his death Jing Province passed to Cao Cao. | F118: 二人の息子のはざまで | G118: 八俊の一人と称された劉表は荊州を守ったが、二人の息子を前に迷い続けた。 | H118: 劉表は八俊の一人として名高い士人で、荊州を治めて乱世の避難所とした。だが長子・劉琦と次子・劉琮のあいだで後継を定められず、その死後、荊州は曹操の手に渡った。 | I118: 在兩個兒子之間 | J118: 號稱八俊之一的劉表守住了荊州，卻在兩個兒子之間猶豫不決。 | K118: 劉表是名列八俊的名士，治理荊州，使其成為亂世中的避難之地。但他在長子劉琦與次子劉琮之間定不下繼承人，死後荊州便落入曹操之手。 | L118: 两个儿子之间 | M118: 号称「八俊」之一的刘表守住了荆州，却在两个儿子之间犹豫不决。 | N118: 刘表是名列「八俊」的名士，治理荆州，使之成为乱世中的避难之地。但他在长子刘琦与次子刘琮之间迟迟定不下继承人，死后荆州落入曹操之手。 | O118: Entre Dois Filhos | P118: Liu Biao, um dos Oito Notáveis, defendeu Jing, mas hesitou entre os dois filhos. | Q118: Liu Biao, letrado célebre como um dos Oito Notáveis, governou Jing e fez dela um refúgio em tempos de caos. Mas não conseguiu escolher herdeiro entre o primogênito Liu Qi e o segundo filho Liu Cong, e após sua morte Jing caiu nas mãos de Cao Cao. | R118: Entre Dois Filhos | S118: Liu Biao, um dos Oito Notáveis, defendeu Jingzhou mas hesitou entre os dois filhos. | T118: Liu Biao, letrado afamado como um dos Oito Notáveis, governou Jingzhou e fez dela um refúgio em tempos de caos. Mas não conseguiu escolher entre o primogénito Liu Qi e o segundo filho Liu Cong, e após a sua morte Jingzhou passou para Cao Cao. | U118: Tra due figli | V118: Liu Biao, annoverato tra gli Otto Eccellenti, difese Jingzhou ma esitò tra i due figli. | W118: Liu Biao, letterato celebre come uno degli Otto Eccellenti, governò Jingzhou facendone un rifugio in tempi di caos. Ma non seppe scegliere l'erede tra il primogenito Liu Qi e il secondo figlio Liu Cong, e dopo la sua morte Jingzhou passò a Cao Cao. | X118: Entre dos hijos | Y118: Liu Biao, uno de los Ocho Talentos, defendió Jing, pero vaciló entre sus dos hijos. | Z118: Liu Biao, letrado célebre como uno de los Ocho Talentos, gobernó Jing y la convirtió en refugio en tiempos de caos. Pero no supo elegir heredero entre su primogénito Liu Qi y su segundo hijo Liu Cong, y a su muerte Jing pasó a manos de Cao Cao. | AA118: Хоёр хүүгийн дунд | AB118: Найман сайн эрийн нэг гэгдсэн Лю Бяо Цзинчжоуг сахисан ч хоёр хүүгийнхээ дунд эргэлзэв. | AC118: Лю Бяо найман сайн эрийн нэг хэмээн алдаршсан эрдэмтэн бөгөөд Цзинчжоуг засаж самуун цагийн хоргодох газар болгосон юм. Гэвч ууган хүү Лю Ци, отгон хүү Лю Цун хоёрын дундаас залгамжлагчаа тогтоож чадаагүй тул нас барсны дараа Цзинчжоу Цао Цаод шилжжээ. | AD118: 荆州刘表

Sheet 비용표
A1: 구분 | B1: 키 | C1: 값 | D1: 설명
A2: 카드 단가 | B2: S | C2: 10 | D2: S급 카드 1장
A3: 카드 단가 | B3: E | C3: 10 | D3: E급(헌제) 카드 1장
A4: 카드 단가 | B4: A | C4: 6 | D4: A급 카드 1장
A5: 카드 단가 | B5: B | C5: 4 | D5: B급 카드 1장
A6: 카드 단가 | B6: C | C6: 2 | D6: C급 — 가챠에 없고 전투 보상으로만 나온다
A7: 카드 단가 | B7: D | C7: 2 | D7: D급 — 가챠에 없고 전투 보상으로만 나온다
A8: 품목 배수 | B8: 병기 | C8: 3 | D8: 병기 비용 = 대장간 해금 Lv × 이 값
A9: 품목 배수 | B9: 아이템 | C9: 2 | D9: 아이템 비용 = 시장 해금 Lv × 이 값
A11: 등급표
A12: 등급 | B12: 비용 하한 | C12: 점수 | D12: 설명
A13: 일반 | B13: 0 | C13: 50
A14: 희귀 | B14: 15 | C14: 100
A15: 영웅 | B15: 28 | C15: 200
A16: 전설 | B16: 34 | C16: 300 | D16: 고유기술 SP −1 · 진영 SP +1은 전설 이상만
A17: 천하 | B17: 50 | C17: 500 | D17: S급 다섯 — 5칸 상한에서 비용의 천장 (2026-10-14)
A19: 노란 칸(파란 글자)만 고치면 「칸」 · 「컬렉션」 시트의 비용 · 등급 · 점수가 다시 계산된다. 값은 2026-10-13 기획 세션 초안이다(3차: 카드는 컬렉션마다 장수당 1장). 2026-10-14: 칸 5개 상한에 맞춰 전설 42 → 34, 천하 60 → 50.

Sheet 칸
A1: 컬렉션 # | B1: 칸 # | C1: 종류 | D1: 대상 | E1: 수 | F1: 등급 / 해금 Lv | G1: 단가 | H1: 비용 | I1: 조건 누적 (보조)
A2: 1 | B2: 1 | C2: 카드 | D2: 유비 | E2: 1 | F2: S | G2: =IF(C2="카드",INDEX(비용표!$C$2:$C$7,MATCH(F2,비용표!$B$2:$B$7,0)),F2*INDEX(비용표!$C$8:$C$9,MATCH(C2,비용표!$B$8:$B$9,0))) | H2: =G2*E2 | I2: =IF(C2="카드",D2&E2,"["&C2&"] "&D2)
A3: 1 | B3: 2 | C3: 카드 | D3: 관우 | E3: 1 | F3: S | G3: =IF(C3="카드",INDEX(비용표!$C$2:$C$7,MATCH(F3,비용표!$B$2:$B$7,0)),F3*INDEX(비용표!$C$8:$C$9,MATCH(C3,비용표!$B$8:$B$9,0))) | H3: =G3*E3 | I3: =IF(A3=A2,I2&" · ","")&IF(C3="카드",D3&E3,"["&C3&"] "&D3)
A4: 1 | B4: 3 | C4: 카드 | D4: 장비 | E4: 1 | F4: S | G4: =IF(C4="카드",INDEX(비용표!$C$2:$C$7,MATCH(F4,비용표!$B$2:$B$7,0)),F4*INDEX(비용표!$C$8:$C$9,MATCH(C4,비용표!$B$8:$B$9,0))) | H4: =G4*E4 | I4: =IF(A4=A3,I3&" · ","")&IF(C4="카드",D4&E4,"["&C4&"] "&D4)
A5: 2 | B5: 1 | C5: 카드 | D5: 유비 | E5: 1 | F5: S | G5: =IF(C5="카드",INDEX(비용표!$C$2:$C$7,MATCH(F5,비용표!$B$2:$B$7,0)),F5*INDEX(비용표!$C$8:$C$9,MATCH(C5,비용표!$B$8:$B$9,0))) | H5: =G5*E5 | I5: =IF(A5=A4,I4&" · ","")&IF(C5="카드",D5&E5,"["&C5&"] "&D5)
A6: 2 | B6: 2 | C6: 카드 | D6: 조조 | E6: 1 | F6: S | G6: =IF(C6="카드",INDEX(비용표!$C$2:$C$7,MATCH(F6,비용표!$B$2:$B$7,0)),F6*INDEX(비용표!$C$8:$C$9,MATCH(C6,비용표!$B$8:$B$9,0))) | H6: =G6*E6 | I6: =IF(A6=A5,I5&" · ","")&IF(C6="카드",D6&E6,"["&C6&"] "&D6)
A7: 2 | B7: 3 | C7: 카드 | D7: 손견 | E7: 1 | F7: S | G7: =IF(C7="카드",INDEX(비용표!$C$2:$C$7,MATCH(F7,비용표!$B$2:$B$7,0)),F7*INDEX(비용표!$C$8:$C$9,MATCH(C7,비용표!$B$8:$B$9,0))) | H7: =G7*E7 | I7: =IF(A7=A6,I6&" · ","")&IF(C7="카드",D7&E7,"["&C7&"] "&D7)
A8: 2 | B8: 4 | C8: 아이템 | D8: 태평요술 | E8: 1 | F8: 3 | G8: =IF(C8="카드",INDEX(비용표!$C$2:$C$7,MATCH(F8,비용표!$B$2:$B$7,0)),F8*INDEX(비용표!$C$8:$C$9,MATCH(C8,비용표!$B$8:$B$9,0))) | H8: =G8*E8 | I8: =IF(A8=A7,I7&" · ","")&IF(C8="카드",D8&E8,"["&C8&"] "&D8)
A9: 3 | B9: 1 | C9: 카드 | D9: 관우 | E9: 1 | F9: S | G9: =IF(C9="카드",INDEX(비용표!$C$2:$C$7,MATCH(F9,비용표!$B$2:$B$7,0)),F9*INDEX(비용표!$C$8:$C$9,MATCH(C9,비용표!$B$8:$B$9,0))) | H9: =G9*E9 | I9: =IF(A9=A8,I8&" · ","")&IF(C9="카드",D9&E9,"["&C9&"] "&D9)
A10: 3 | B10: 2 | C10: 카드 | D10: 화웅 | E10: 1 | F10: A | G10: =IF(C10="카드",INDEX(비용표!$C$2:$C$7,MATCH(F10,비용표!$B$2:$B$7,0)),F10*INDEX(비용표!$C$8:$C$9,MATCH(C10,비용표!$B$8:$B$9,0))) | H10: =G10*E10 | I10: =IF(A10=A9,I9&" · ","")&IF(C10="카드",D10&E10,"["&C10&"] "&D10)
A11: 3 | B11: 3 | C11: 카드 | D11: 조조 | E11: 1 | F11: S | G11: =IF(C11="카드",INDEX(비용표!$C$2:$C$7,MATCH(F11,비용표!$B$2:$B$7,0)),F11*INDEX(비용표!$C$8:$C$9,MATCH(C11,비용표!$B$8:$B$9,0))) | H11: =G11*E11 | I11: =IF(A11=A10,I10&" · ","")&IF(C11="카드",D11&E11,"["&C11&"] "&D11)
A12: 4 | B12: 1 | C12: 카드 | D12: 여포 | E12: 1 | F12: S | G12: =IF(C12="카드",INDEX(비용표!$C$2:$C$7,MATCH(F12,비용표!$B$2:$B$7,0)),F12*INDEX(비용표!$C$8:$C$9,MATCH(C12,비용표!$B$8:$B$9,0))) | H12: =G12*E12 | I12: =IF(A12=A11,I11&" · ","")&IF(C12="카드",D12&E12,"["&C12&"] "&D12)
A13: 4 | B13: 2 | C13: 카드 | D13: 유비 | E13: 1 | F13: S | G13: =IF(C13="카드",INDEX(비용표!$C$2:$C$7,MATCH(F13,비용표!$B$2:$B$7,0)),F13*INDEX(비용표!$C$8:$C$9,MATCH(C13,비용표!$B$8:$B$9,0))) | H13: =G13*E13 | I13: =IF(A13=A12,I12&" · ","")&IF(C13="카드",D13&E13,"["&C13&"] "&D13)
A14: 4 | B14: 3 | C14: 카드 | D14: 관우 | E14: 1 | F14: S | G14: =IF(C14="카드",INDEX(비용표!$C$2:$C$7,MATCH(F14,비용표!$B$2:$B$7,0)),F14*INDEX(비용표!$C$8:$C$9,MATCH(C14,비용표!$B$8:$B$9,0))) | H14: =G14*E14 | I14: =IF(A14=A13,I13&" · ","")&IF(C14="카드",D14&E14,"["&C14&"] "&D14)
A15: 4 | B15: 4 | C15: 카드 | D15: 장비 | E15: 1 | F15: S | G15: =IF(C15="카드",INDEX(비용표!$C$2:$C$7,MATCH(F15,비용표!$B$2:$B$7,0)),F15*INDEX(비용표!$C$8:$C$9,MATCH(C15,비용표!$B$8:$B$9,0))) | H15: =G15*E15 | I15: =IF(A15=A14,I14&" · ","")&IF(C15="카드",D15&E15,"["&C15&"] "&D15)
A16: 5 | B16: 1 | C16: 카드 | D16: 원소 | E16: 1 | F16: C | G16: =IF(C16="카드",INDEX(비용표!$C$2:$C$7,MATCH(F16,비용표!$B$2:$B$7,0)),F16*INDEX(비용표!$C$8:$C$9,MATCH(C16,비용표!$B$8:$B$9,0))) | H16: =G16*E16 | I16: =IF(A16=A15,I15&" · ","")&IF(C16="카드",D16&E16,"["&C16&"] "&D16)
